<?xml version='1.0' encoding='utf-8'?>
<sdf version="1.9">
  <model name="hop">
    <pose>2 0 0.85 0 0 0</pose>
    <link name="base_link">
      <pose>0 0 0 0 0 0</pose>
      <inertial>
        <pose>2.605303324e-09 2.043051118e-05 0.7496920173 0 0 0</pose>
        <mass>0.040941821553539655</mass>
        <inertia>
          <ixx>3.2e-05</ixx>
          <ixy>-0.0</ixy>
          <ixz>-0.0</ixz>
          <iyy>8.8e-05</iyy>
          <iyz>-0.0</iyz>
          <izz>0.00012</izz>
        </inertia>
      </inertial>
      <visual name="base_link_visual">
        <pose>0 0 0 0 0 0</pose>
        <geometry>
          <mesh>
            <uri>model://x500_hop/meshes/base_link.stl</uri>
            <scale>0.001 0.001 0.001</scale>
          </mesh>
        </geometry>
                <material>
          <ambient>0.7 0.7 0.7 1</ambient>
          <diffuse>0.7 0.7 0.7 1</diffuse>
          <specular>0.3 0.3 0.3 1</specular>
        </material>
      </visual>
      <collision name="base_link_collision">
        <pose>0 0 0 0 0 0</pose>
        <geometry>
          <mesh>
            <uri>model://x500_hop/meshes/base_link.stl</uri>
            <scale>0.001 0.001 0.001</scale>
          </mesh>
        </geometry>
      </collision>

      <sensor name="air_pressure_sensor" type="air_pressure">
        <always_on>1</always_on>
        <update_rate>50</update_rate>
        <air_pressure>
          <pressure>
            <noise type="gaussian">
              <mean>0</mean>
              <stddev>3</stddev>
            </noise>
          </pressure>
        </air_pressure>
      </sensor>
      <sensor name="magnetometer_sensor" type="magnetometer">
        <always_on>1</always_on>
        <update_rate>100</update_rate>
        <magnetometer>
          <x><noise type="gaussian"><stddev>0.0001</stddev></noise></x>
          <y><noise type="gaussian"><stddev>0.0001</stddev></noise></y>
          <z><noise type="gaussian"><stddev>0.0001</stddev></noise></z>
        </magnetometer>
      </sensor>
      <sensor name="imu_sensor" type="imu">
        <always_on>1</always_on>
        <update_rate>250</update_rate>
        <imu>
          <angular_velocity>
            <x><noise type="gaussian"><mean>0</mean><stddev>0.0008726646</stddev></noise></x>
            <y><noise type="gaussian"><mean>0</mean><stddev>0.0008726646</stddev></noise></y>
            <z><noise type="gaussian"><mean>0</mean><stddev>0.0008726646</stddev></noise></z>
          </angular_velocity>
          <linear_acceleration>
            <x><noise type="gaussian"><mean>0</mean><stddev>0.00637</stddev></noise></x>
            <y><noise type="gaussian"><mean>0</mean><stddev>0.00637</stddev></noise></y>
            <z><noise type="gaussian"><mean>0</mean><stddev>0.00686</stddev></noise></z>
          </linear_acceleration>
        </imu>
      </sensor>
      <sensor name="navsat_sensor" type="navsat">
        <always_on>1</always_on>
        <update_rate>30</update_rate>
      </sensor>
    </link>
    <link name="frame_arm_1">
      <pose>0.046528 0.031724 0.750493 0 0 0</pose>
      <inertial>
        <pose>0.04808517664 0.0625831989 0.02771925293 0 0 0</pose>
        <mass>0.052778741103259794</mass>
        <inertia>
          <ixx>0.000131</ixx>
          <ixy>-0.000121</ixy>
          <ixz>2e-06</ixz>
          <iyy>0.000131</iyy>
          <iyz>2e-06</iyz>
          <izz>0.000251</izz>
        </inertia>
      </inertial>
      <visual name="old_component__1__1_visual">
        <pose>-0.046528 -0.031724 -0.750493 0 0 0</pose>
        <geometry>
          <mesh>
            <uri>model://x500_hop/meshes/frame_arm_1.stl</uri>
            <scale>0.001 0.001 0.001</scale>
          </mesh>
        </geometry>
                <material>
          <ambient>0.7 0.7 0.7 1</ambient>
          <diffuse>0.7 0.7 0.7 1</diffuse>
          <specular>0.3 0.3 0.3 1</specular>
        </material>
      </visual>
      <collision name="old_component__1__1_collision">
        <pose>-0.046528 -0.031724 -0.750493 0 0 0</pose>
        <geometry>
          <mesh>
            <uri>model://x500_hop/meshes/frame_arm_1.stl</uri>
            <scale>0.001 0.001 0.001</scale>
          </mesh>
        </geometry>
      </collision>
    </link>
    <link name="frame_arm_2">
      <pose>-0.032032 0.04622 0.750493 0 0 0</pose>
      <inertial>
        <pose>-0.06258316505 0.04808521049 0.02771925293 0 0 0</pose>
        <mass>0.052778741103259794</mass>
        <inertia>
          <ixx>0.000131</ixx>
          <ixy>0.000121</ixy>
          <ixz>-2e-06</ixz>
          <iyy>0.000131</iyy>
          <iyz>2e-06</iyz>
          <izz>0.000251</izz>
        </inertia>
      </inertial>
      <visual name="old_component__2__1_visual">
        <pose>0.032032 -0.04622 -0.750493 0 0 0</pose>
        <geometry>
          <mesh>
            <uri>model://x500_hop/meshes/frame_arm_2.stl</uri>
            <scale>0.001 0.001 0.001</scale>
          </mesh>
        </geometry>
                <material>
          <ambient>0.7 0.7 0.7 1</ambient>
          <diffuse>0.7 0.7 0.7 1</diffuse>
          <specular>0.3 0.3 0.3 1</specular>
        </material>
      </visual>
      <collision name="old_component__2__1_collision">
        <pose>0.032032 -0.04622 -0.750493 0 0 0</pose>
        <geometry>
          <mesh>
            <uri>model://x500_hop/meshes/frame_arm_2.stl</uri>
            <scale>0.001 0.001 0.001</scale>
          </mesh>
        </geometry>
      </collision>
    </link>
    <link name="frame_arm_3">
      <pose>-0.046528 -0.03234 0.750493 0 0 0</pose>
      <inertial>
        <pose>-0.04808517664 -0.0625831312 0.02771925293 0 0 0</pose>
        <mass>0.052778741103259794</mass>
        <inertia>
          <ixx>0.000131</ixx>
          <ixy>-0.000121</ixy>
          <ixz>-2e-06</ixz>
          <iyy>0.000131</iyy>
          <iyz>-2e-06</iyz>
          <izz>0.000251</izz>
        </inertia>
      </inertial>
      <visual name="old_component__3__1_visual">
        <pose>0.046528 0.03234 -0.750493 0 0 0</pose>
        <geometry>
          <mesh>
            <uri>model://x500_hop/meshes/frame_arm_3.stl</uri>
            <scale>0.001 0.001 0.001</scale>
          </mesh>
        </geometry>
                <material>
          <ambient>0.7 0.7 0.7 1</ambient>
          <diffuse>0.7 0.7 0.7 1</diffuse>
          <specular>0.3 0.3 0.3 1</specular>
        </material>
      </visual>
      <collision name="old_component__3__1_collision">
        <pose>0.046528 0.03234 -0.750493 0 0 0</pose>
        <geometry>
          <mesh>
            <uri>model://x500_hop/meshes/frame_arm_3.stl</uri>
            <scale>0.001 0.001 0.001</scale>
          </mesh>
        </geometry>
      </collision>
    </link>
    <link name="frame_arm_4">
      <pose>0.046528 -0.03234 0.750493 0 0 0</pose>
      <inertial>
        <pose>0.04808716505 -0.06258114279 0.02771925293 0 0 0</pose>
        <mass>0.052778741103259794</mass>
        <inertia>
          <ixx>0.000131</ixx>
          <ixy>0.000121</ixy>
          <ixz>2e-06</ixz>
          <iyy>0.000131</iyy>
          <iyz>-2e-06</iyz>
          <izz>0.000251</izz>
        </inertia>
      </inertial>
      <visual name="old_component__4__1_visual">
        <pose>-0.046528 0.03234 -0.750493 0 0 0</pose>
        <geometry>
          <mesh>
            <uri>model://x500_hop/meshes/frame_arm_4.stl</uri>
            <scale>0.001 0.001 0.001</scale>
          </mesh>
        </geometry>
                <material>
          <ambient>0.7 0.7 0.7 1</ambient>
          <diffuse>0.7 0.7 0.7 1</diffuse>
          <specular>0.3 0.3 0.3 1</specular>
        </material>
      </visual>
      <collision name="old_component__4__1_collision">
        <pose>-0.046528 0.03234 -0.750493 0 0 0</pose>
        <geometry>
          <mesh>
            <uri>model://x500_hop/meshes/frame_arm_4.stl</uri>
            <scale>0.001 0.001 0.001</scale>
          </mesh>
        </geometry>
      </collision>
    </link>
    <link name="landing_gear_1">
      <pose>-0.046528 -0.03234 0.748891 0 0 0</pose>
      <inertial>
        <pose>0.04195066374 9.666322671e-08 -0.009991116066 0 0 0</pose>
        <mass>0.022153315501877338</mass>
        <inertia>
          <ixx>1e-06</ixx>
          <ixy>0.0</ixy>
          <ixz>0.0</ixz>
          <iyy>0.000135</iyy>
          <iyz>-0.0</iyz>
          <izz>0.000135</izz>
        </inertia>
      </inertial>
      <visual name="old_component__5__1_visual">
        <pose>0.046528 0.03234 -0.748891 0 0 0</pose>
        <geometry>
          <mesh>
            <uri>model://x500_hop/meshes/landing_gear_1.stl</uri>
            <scale>0.001 0.001 0.001</scale>
          </mesh>
        </geometry>
                <material>
          <ambient>0.7 0.7 0.7 1</ambient>
          <diffuse>0.7 0.7 0.7 1</diffuse>
          <specular>0.3 0.3 0.3 1</specular>
        </material>
      </visual>
      <collision name="old_component__5__1_collision">
        <pose>0.046528 0.03234 -0.748891 0 0 0</pose>
        <geometry>
          <mesh>
            <uri>model://x500_hop/meshes/landing_gear_1.stl</uri>
            <scale>0.001 0.001 0.001</scale>
          </mesh>
        </geometry>
      </collision>
    </link>
    <link name="landing_gear_2">
      <pose>-0.046528 0.031724 0.748891 0 0 0</pose>
      <inertial>
        <pose>0.04195066374 -3.127095397e-08 -0.009991116066 0 0 0</pose>
        <mass>0.022153315501877338</mass>
        <inertia>
          <ixx>1e-06</ixx>
          <ixy>0.0</ixy>
          <ixz>0.0</ixz>
          <iyy>0.000135</iyy>
          <iyz>-0.0</iyz>
          <izz>0.000135</izz>
        </inertia>
      </inertial>
      <visual name="old_component__6__1_visual">
        <pose>0.046528 -0.031724 -0.748891 0 0 0</pose>
        <geometry>
          <mesh>
            <uri>model://x500_hop/meshes/landing_gear_2.stl</uri>
            <scale>0.001 0.001 0.001</scale>
          </mesh>
        </geometry>
                <material>
          <ambient>0.7 0.7 0.7 1</ambient>
          <diffuse>0.7 0.7 0.7 1</diffuse>
          <specular>0.3 0.3 0.3 1</specular>
        </material>
      </visual>
      <collision name="old_component__6__1_collision">
        <pose>0.046528 -0.031724 -0.748891 0 0 0</pose>
        <geometry>
          <mesh>
            <uri>model://x500_hop/meshes/landing_gear_2.stl</uri>
            <scale>0.001 0.001 0.001</scale>
          </mesh>
        </geometry>
      </collision>
    </link>
    <link name="frame_mount">
      <pose>-0.031466 -0.048391 0.787298 0 0 0</pose>
      <inertial>
        <pose>0.03146602987 0.04808260441 0.0008261135785 0 0 0</pose>
        <mass>0.1058764952504954</mass>
        <inertia>
          <ixx>9.6e-05</ixx>
          <ixy>0.0</ixy>
          <ixz>-0.0</ixz>
          <iyy>9.4e-05</iyy>
          <iyz>-0.0</iyz>
          <izz>0.00019</izz>
        </inertia>
      </inertial>
      <visual name="old_component__7__1_visual">
        <pose>0.031466 0.048391 -0.787298 0 0 0</pose>
        <geometry>
          <mesh>
            <uri>model://x500_hop/meshes/frame_mount.stl</uri>
            <scale>0.001 0.001 0.001</scale>
          </mesh>
        </geometry>
                <material>
          <ambient>0.7 0.7 0.7 1</ambient>
          <diffuse>0.7 0.7 0.7 1</diffuse>
          <specular>0.3 0.3 0.3 1</specular>
        </material>
      </visual>
      <collision name="old_component__7__1_collision">
        <pose>0.031466 0.048391 -0.787298 0 0 0</pose>
        <geometry>
          <mesh>
            <uri>model://x500_hop/meshes/frame_mount.stl</uri>
            <scale>0.001 0.001 0.001</scale>
          </mesh>
        </geometry>
      </collision>
    </link>
    <link name="motor_mount_1">
      <pose>0.158901 -0.15922 0.787543 0 0 0</pose>
      <inertial>
        <pose>1.780720014e-06 -3.401592858e-06 0.01654829644 0 0 0</pose>
        <mass>0.06901485659461869</mass>
        <inertia>
          <ixx>1.3e-05</ixx>
          <ixy>0.0</ixy>
          <ixz>-0.0</ixz>
          <iyy>1.3e-05</iyy>
          <iyz>0.0</iyz>
          <izz>7e-06</izz>
        </inertia>
      </inertial>
      <visual name="old_component__8__1_visual">
        <pose>-0.158901 0.15922 -0.787543 0 0 0</pose>
        <geometry>
          <mesh>
            <uri>model://x500_hop/meshes/motor_mount_1.stl</uri>
            <scale>0.001 0.001 0.001</scale>
          </mesh>
        </geometry>
                <material>
          <ambient>0.7 0.7 0.7 1</ambient>
          <diffuse>0.7 0.7 0.7 1</diffuse>
          <specular>0.3 0.3 0.3 1</specular>
        </material>
      </visual>
      <collision name="old_component__8__1_collision">
        <pose>-0.158901 0.15922 -0.787543 0 0 0</pose>
        <geometry>
          <mesh>
            <uri>model://x500_hop/meshes/motor_mount_1.stl</uri>
            <scale>0.001 0.001 0.001</scale>
          </mesh>
        </geometry>
      </collision>
    </link>
    <link name="motor_mount_2">
      <pose>0.158912 0.158593 0.787543 0 0 0</pose>
      <inertial>
        <pose>1.471016667e-06 -3.580902376e-06 0.01654829644 0 0 0</pose>
        <mass>0.06901485659461874</mass>
        <inertia>
          <ixx>1.3e-05</ixx>
          <ixy>0.0</ixy>
          <ixz>-0.0</ixz>
          <iyy>1.3e-05</iyy>
          <iyz>0.0</iyz>
          <izz>7e-06</izz>
        </inertia>
      </inertial>
      <visual name="old_component__9__1_visual">
        <pose>-0.158912 -0.158593 -0.787543 0 0 0</pose>
        <geometry>
          <mesh>
            <uri>model://x500_hop/meshes/motor_mount_2.stl</uri>
            <scale>0.001 0.001 0.001</scale>
          </mesh>
        </geometry>
                <material>
          <ambient>0.7 0.7 0.7 1</ambient>
          <diffuse>0.7 0.7 0.7 1</diffuse>
          <specular>0.3 0.3 0.3 1</specular>
        </material>
      </visual>
      <collision name="old_component__9__1_collision">
        <pose>-0.158912 -0.158593 -0.787543 0 0 0</pose>
        <geometry>
          <mesh>
            <uri>model://x500_hop/meshes/motor_mount_2.stl</uri>
            <scale>0.001 0.001 0.001</scale>
          </mesh>
        </geometry>
      </collision>
    </link>
    <link name="motor_mount_3">
      <pose>-0.158901 0.158604 0.787543 0 0 0</pose>
      <inertial>
        <pose>1.650326185e-06 -3.890605722e-06 0.01654829644 0 0 0</pose>
        <mass>0.0690148565946187</mass>
        <inertia>
          <ixx>1.3e-05</ixx>
          <ixy>0.0</ixy>
          <ixz>-0.0</ixz>
          <iyy>1.3e-05</iyy>
          <iyz>0.0</iyz>
          <izz>7e-06</izz>
        </inertia>
      </inertial>
      <visual name="old_component__10__1_visual">
        <pose>0.158901 -0.158604 -0.787543 0 0 0</pose>
        <geometry>
          <mesh>
            <uri>model://x500_hop/meshes/motor_mount_3.stl</uri>
            <scale>0.001 0.001 0.001</scale>
          </mesh>
        </geometry>
                <material>
          <ambient>0.7 0.7 0.7 1</ambient>
          <diffuse>0.7 0.7 0.7 1</diffuse>
          <specular>0.3 0.3 0.3 1</specular>
        </material>
      </visual>
      <collision name="old_component__10__1_collision">
        <pose>0.158901 -0.158604 -0.787543 0 0 0</pose>
        <geometry>
          <mesh>
            <uri>model://x500_hop/meshes/motor_mount_3.stl</uri>
            <scale>0.001 0.001 0.001</scale>
          </mesh>
        </geometry>
      </collision>
    </link>
    <link name="motor_mount_4">
      <pose>-0.158912 -0.159209 0.787543 0 0 0</pose>
      <inertial>
        <pose>1.96002953e-06 -3.711296205e-06 0.01654829644 0 0 0</pose>
        <mass>0.06901485659461869</mass>
        <inertia>
          <ixx>1.3e-05</ixx>
          <ixy>0.0</ixy>
          <ixz>-0.0</ixz>
          <iyy>1.3e-05</iyy>
          <iyz>0.0</iyz>
          <izz>7e-06</izz>
        </inertia>
      </inertial>
      <visual name="old_component__11__1_visual">
        <pose>0.158912 0.159209 -0.787543 0 0 0</pose>
        <geometry>
          <mesh>
            <uri>model://x500_hop/meshes/motor_mount_4.stl</uri>
            <scale>0.001 0.001 0.001</scale>
          </mesh>
        </geometry>
                <material>
          <ambient>0.7 0.7 0.7 1</ambient>
          <diffuse>0.7 0.7 0.7 1</diffuse>
          <specular>0.3 0.3 0.3 1</specular>
        </material>
      </visual>
      <collision name="old_component__11__1_collision">
        <pose>0.158912 0.159209 -0.787543 0 0 0</pose>
        <geometry>
          <mesh>
            <uri>model://x500_hop/meshes/motor_mount_4.stl</uri>
            <scale>0.001 0.001 0.001</scale>
          </mesh>
        </geometry>
      </collision>
    </link>
    <link name="payload_bracket_2">
      <pose>0 -0.000308 0.788949 0 0 0</pose>
      <inertial>
        <pose>-1.723066134e-15 3.385045852e-08 0.0250001216 0 0 0</pose>
        <mass>0.5796</mass>
        <inertia>
          <ixx>0.000604</ixx>
          <ixy>-0.0</ixy>
          <ixz>-0.0</ixz>
          <iyy>0.000604</iyy>
          <iyz>-0.0</iyz>
          <izz>0.000966</izz>
        </inertia>
      </inertial>
      <visual name="old_component__13__1_visual">
        <pose>0 0.000308 -0.788949 0 0 0</pose>
        <geometry>
          <mesh>
            <uri>model://x500_hop/meshes/payload_bracket_2.stl</uri>
            <scale>0.001 0.001 0.001</scale>
          </mesh>
        </geometry>
                <material>
          <ambient>0.7 0.7 0.7 1</ambient>
          <diffuse>0.7 0.7 0.7 1</diffuse>
          <specular>0.3 0.3 0.3 1</specular>
        </material>
      </visual>
      <collision name="old_component__13__1_collision">
        <pose>0 0.000308 -0.788949 0 0 0</pose>
        <geometry>
          <mesh>
            <uri>model://x500_hop/meshes/payload_bracket_2.stl</uri>
            <scale>0.001 0.001 0.001</scale>
          </mesh>
        </geometry>
      </collision>
    </link>
    <link name="payload_bracket_1">
      <pose>-0.055 -0.000308 0.8785 0 0 0</pose>
      <inertial>
        <pose>0.15 -0.0004999661495 -0.0284548784 0 0 0</pose>
        <mass>0.521</mass>
        <inertia>
          <ixx>1.5e-05</ixx>
          <ixy>-0.0</ixy>
          <ixz>0.0</ixz>
          <iyy>1.5e-05</iyy>
          <iyz>0.0</iyz>
          <izz>2.1e-05</izz>
        </inertia>
      </inertial>
      <visual name="old_component__12__1_visual">
        <pose>0 0.000308 -0.788949 0 0 0</pose>
        <geometry>
          <mesh>
            <uri>model://x500_hop/meshes/payload_bracket_1.stl</uri>
            <scale>0.001 0.001 0.001</scale>
          </mesh>
        </geometry>
                <material>
          <ambient>0.7 0.7 0.7 1</ambient>
          <diffuse>0.7 0.7 0.7 1</diffuse>
          <specular>0.3 0.3 0.3 1</specular>
        </material>
      </visual>
      <collision name="old_component__12__1_collision">
        <pose>0 0.000308 -0.788949 0 0 0</pose>
        <geometry>
          <mesh>
            <uri>model://x500_hop/meshes/payload_bracket_1.stl</uri>
            <scale>0.001 0.001 0.001</scale>
          </mesh>
        </geometry>
      </collision>
    </link>
    <link name="arm_mount_bracket">
      <pose>-0.139528 0.031724 0.738891 0 0 0</pose>
      <inertial>
        <pose>0.02504604942 -0.03202875477 -0.009462011097 0 0 0</pose>
        <mass>0.02880476961581307</mass>
        <inertia>
          <ixx>2e-05</ixx>
          <ixy>0.0</ixy>
          <ixz>0.0</ixz>
          <iyy>1.2e-05</iyy>
          <iyz>0.0</iyz>
          <izz>3e-05</izz>
        </inertia>
      </inertial>
      <visual name="old_component__14__1_visual">
        <pose>0.139528 -0.031724 -0.738891 0 0 0</pose>
        <geometry>
          <mesh>
            <uri>model://x500_hop/meshes/arm_mount_bracket.stl</uri>
            <scale>0.001 0.001 0.001</scale>
          </mesh>
        </geometry>
                <material>
          <ambient>0.7 0.7 0.7 1</ambient>
          <diffuse>0.7 0.7 0.7 1</diffuse>
          <specular>0.3 0.3 0.3 1</specular>
        </material>
      </visual>
      <collision name="old_component__14__1_collision">
        <pose>0.139528 -0.031724 -0.738891 0 0 0</pose>
        <geometry>
          <mesh>
            <uri>model://x500_hop/meshes/arm_mount_bracket.stl</uri>
            <scale>0.001 0.001 0.001</scale>
          </mesh>
        </geometry>
      </collision>
    </link>
    <link name="robotic_arm_base">
      <pose>-0.090638 0.003586 0.732641 0 0 0</pose>
      <inertial>
        <pose>-0.02416322554 -0.003900040815 0.01004745909 0 0 0</pose>
        <mass>0.06496477624065831</mass>
        <inertia>
          <ixx>1e-05</ixx>
          <ixy>-0.0</ixy>
          <ixz>-0.0</ixz>
          <iyy>1.7e-05</iyy>
          <iyz>-0.0</iyz>
          <izz>1.1e-05</izz>
        </inertia>
      </inertial>
      <visual name="old_component__15__1_visual">
        <pose>0.090638 -0.003586 -0.732641 0 0 0</pose>
        <geometry>
          <mesh>
            <uri>model://x500_hop/meshes/robotic_arm_base.stl</uri>
            <scale>0.001 0.001 0.001</scale>
          </mesh>
        </geometry>
                <material>
          <ambient>0.7 0.7 0.7 1</ambient>
          <diffuse>0.7 0.7 0.7 1</diffuse>
          <specular>0.3 0.3 0.3 1</specular>
        </material>
      </visual>
      <collision name="old_component__15__1_collision">
        <pose>0.090638 -0.003586 -0.732641 0 0 0</pose>
        <geometry>
          <mesh>
            <uri>model://x500_hop/meshes/robotic_arm_base.stl</uri>
            <scale>0.001 0.001 0.001</scale>
          </mesh>
        </geometry>
      </collision>
    </link>
    <link name="robotic_arm_link_1">
      <pose>-0.125325 -0.000314 0.716441 0 0 0</pose>
      <inertial>
        <pose>-0.01122049466 0.003097382027 -0.01563841273 0 0 0</pose>
        <mass>0.04239336565154814</mass>
        <inertia>
          <ixx>6.5e-05</ixx>
          <ixy>8e-06</ixy>
          <ixz>-2.8e-05</ixz>
          <iyy>9.6e-05</iyy>
          <iyz>9e-06</iyz>
          <izz>8.1e-05</izz>
        </inertia>
      </inertial>
      <visual name="old_component__16__1_visual">
        <pose>0.125325 0.000314 -0.716441 0 0 0</pose>
        <geometry>
          <mesh>
            <uri>model://x500_hop/meshes/robotic_arm_link_1.stl</uri>
            <scale>0.001 0.001 0.001</scale>
          </mesh>
        </geometry>
                <material>
          <ambient>0.7 0.7 0.7 1</ambient>
          <diffuse>0.7 0.7 0.7 1</diffuse>
          <specular>0.3 0.3 0.3 1</specular>
        </material>
      </visual>
      <collision name="old_component__16__1_collision">
        <pose>0.125325 0.000314 -0.716441 0 0 0</pose>
        <geometry>
          <mesh>
            <uri>model://x500_hop/meshes/robotic_arm_link_1.stl</uri>
            <scale>0.001 0.001 0.001</scale>
          </mesh>
        </geometry>
      </collision>
    </link>
    <link name="robotic_arm_motor_casing_1">
      <pose>-0.174256 -0.007314 0.682717 0 0 0</pose>
      <inertial>
        <pose>0.0241631951 0.007047415579 -0.003899730512 0 0 0</pose>
        <mass>0.06496477624065831</mass>
        <inertia>
          <ixx>1e-05</ixx>
          <ixy>0.0</ixy>
          <ixz>0.0</ixz>
          <iyy>1.1e-05</iyy>
          <iyz>-0.0</iyz>
          <izz>1.7e-05</izz>
        </inertia>
      </inertial>
      <visual name="old_component__17__1_visual">
        <pose>0.174256 0.007314 -0.682717 0 0 0</pose>
        <geometry>
          <mesh>
            <uri>model://x500_hop/meshes/robotic_arm_motor_casing_1.stl</uri>
            <scale>0.001 0.001 0.001</scale>
          </mesh>
        </geometry>
                <material>
          <ambient>0.7 0.7 0.7 1</ambient>
          <diffuse>0.7 0.7 0.7 1</diffuse>
          <specular>0.3 0.3 0.3 1</specular>
        </material>
      </visual>
      <collision name="old_component__17__1_collision">
        <pose>0.174256 0.007314 -0.682717 0 0 0</pose>
        <geometry>
          <mesh>
            <uri>model://x500_hop/meshes/robotic_arm_motor_casing_1.stl</uri>
            <scale>0.001 0.001 0.001</scale>
          </mesh>
        </geometry>
      </collision>
    </link>
    <link name="robotic_arm_link_2">
      <pose>-0.139569 -0.026514 0.678817 0 0 0</pose>
      <inertial>
        <pose>-3.213022812e-08 0.02077669549 -0.06562878216 0 0 0</pose>
        <mass>0.013524532357919387</mass>
        <inertia>
          <ixx>0.000387</ixx>
          <ixy>0.0</ixy>
          <ixz>-0.0</ixz>
          <iyy>0.000337</iyy>
          <iyz>-9e-06</iyz>
          <izz>0.000108</izz>
        </inertia>
      </inertial>
      <visual name="old_component__18__1_visual">
        <pose>0.139569 0.026514 -0.678817 0 0 0</pose>
        <geometry>
          <mesh>
            <uri>model://x500_hop/meshes/robotic_arm_link_2.stl</uri>
            <scale>0.001 0.001 0.001</scale>
          </mesh>
        </geometry>
                <material>
          <ambient>0.7 0.7 0.7 1</ambient>
          <diffuse>0.7 0.7 0.7 1</diffuse>
          <specular>0.3 0.3 0.3 1</specular>
        </material>
      </visual>
      <collision name="old_component__18__1_collision">
        <pose>0.139569 0.026514 -0.678817 0 0 0</pose>
        <geometry>
          <mesh>
            <uri>model://x500_hop/meshes/robotic_arm_link_2.stl</uri>
            <scale>0.001 0.001 0.001</scale>
          </mesh>
        </geometry>
      </collision>
    </link>
    <link name="robotic_arm_link_3">
      <pose>-0.139569 -0.026514 0.523817 0 0 0</pose>
      <inertial>
        <pose>-3.112324087e-08 0.02624741558 -0.01052349486 0 0 0</pose>
        <mass>0.016283932466536446</mass>
        <inertia>
          <ixx>1.5e-05</ixx>
          <ixy>0.0</ixy>
          <ixz>-0.0</ixz>
          <iyy>1e-05</iyy>
          <iyz>0.0</iyz>
          <izz>9e-06</izz>
        </inertia>
      </inertial>
      <visual name="old_component__19__1_visual">
        <pose>0.139569 0.026514 -0.523817 0 0 0</pose>
        <geometry>
          <mesh>
            <uri>model://x500_hop/meshes/robotic_arm_link_3.stl</uri>
            <scale>0.001 0.001 0.001</scale>
          </mesh>
        </geometry>
                <material>
          <ambient>0.7 0.7 0.7 1</ambient>
          <diffuse>0.7 0.7 0.7 1</diffuse>
          <specular>0.3 0.3 0.3 1</specular>
        </material>
      </visual>
      <collision name="old_component__19__1_collision">
        <pose>0.139569 0.026514 -0.523817 0 0 0</pose>
        <geometry>
          <mesh>
            <uri>model://x500_hop/meshes/robotic_arm_link_3.stl</uri>
            <scale>0.001 0.001 0.001</scale>
          </mesh>
        </geometry>
      </collision>
    </link>
    <link name="robotic_arm_motor_casing_2">
      <pose>-0.143469 -0.007314 0.48913 0 0 0</pose>
      <inertial>
        <pose>0.02394896341 0.0235606891 0.008245861411 0 0 0</pose>
        <mass>0.04239336565154814</mass>
        <inertia>
          <ixx>6.2e-05</ixx>
          <ixy>4e-06</ixy>
          <ixz>1.9e-05</ixz>
          <iyy>7.2e-05</iyy>
          <iyz>-3e-06</iyz>
          <izz>3.5e-05</izz>
        </inertia>
      </inertial>
      <visual name="old_component__20__1_visual">
        <pose>0.143469 0.007314 -0.48913 0 0 0</pose>
        <geometry>
          <mesh>
            <uri>model://x500_hop/meshes/robotic_arm_motor_casing_2.stl</uri>
            <scale>0.001 0.001 0.001</scale>
          </mesh>
        </geometry>
                <material>
          <ambient>0.7 0.7 0.7 1</ambient>
          <diffuse>0.7 0.7 0.7 1</diffuse>
          <specular>0.3 0.3 0.3 1</specular>
        </material>
      </visual>
      <collision name="old_component__20__1_collision">
        <pose>0.143469 0.007314 -0.48913 0 0 0</pose>
        <geometry>
          <mesh>
            <uri>model://x500_hop/meshes/robotic_arm_motor_casing_2.stl</uri>
            <scale>0.001 0.001 0.001</scale>
          </mesh>
        </geometry>
      </collision>
    </link>
    <link name="robotic_arm_connector">
      <pose>-0.109719 0.028886 0.446314 0 0 0</pose>
      <inertial>
        <pose>-3.583369931e-08 -0.01489536408 0.00297277158 0 0 0</pose>
        <mass>0.013524532357919387</mass>
        <inertia>
          <ixx>1e-06</ixx>
          <ixy>-0.0</ixy>
          <ixz>0.0</ixz>
          <iyy>1e-06</iyy>
          <iyz>0.0</iyz>
          <izz>1e-06</izz>
        </inertia>
      </inertial>
      <visual name="old_component__21__1_visual">
        <pose>0.109719 -0.028886 -0.446314 0 0 0</pose>
        <geometry>
          <mesh>
            <uri>model://x500_hop/meshes/robotic_arm_connector.stl</uri>
            <scale>0.001 0.001 0.001</scale>
          </mesh>
        </geometry>
                <material>
          <ambient>0.7 0.7 0.7 1</ambient>
          <diffuse>0.7 0.7 0.7 1</diffuse>
          <specular>0.3 0.3 0.3 1</specular>
        </material>
      </visual>
      <collision name="old_component__21__1_collision">
        <pose>0.109719 -0.028886 -0.446314 0 0 0</pose>
        <geometry>
          <mesh>
            <uri>model://x500_hop/meshes/robotic_arm_connector.stl</uri>
            <scale>0.001 0.001 0.001</scale>
          </mesh>
        </geometry>
      </collision>
    </link>
    <link name="robotic_arm_link_4">
      <pose>-0.109719 0.018936 0.431514 0 0 0</pose>
      <inertial>
        <pose>-7.192509713e-05 -0.0008719393217 -0.02391170597 0 0 0</pose>
        <mass>0.013524532357919387</mass>
        <inertia>
          <ixx>1.5e-05</ixx>
          <ixy>-0.0</ixy>
          <ixz>-0.0</ixz>
          <iyy>1.6e-05</iyy>
          <iyz>-2e-06</iyz>
          <izz>5e-06</izz>
        </inertia>
      </inertial>
      <visual name="old_component__22__1_visual">
        <pose>0.109719 -0.018936 -0.431514 0 0 0</pose>
        <geometry>
          <mesh>
            <uri>model://x500_hop/meshes/robotic_arm_link_4.stl</uri>
            <scale>0.001 0.001 0.001</scale>
          </mesh>
        </geometry>
                <material>
          <ambient>0.7 0.7 0.7 1</ambient>
          <diffuse>0.7 0.7 0.7 1</diffuse>
          <specular>0.3 0.3 0.3 1</specular>
        </material>
      </visual>
      <collision name="old_component__22__1_collision">
        <pose>0.109719 -0.018936 -0.431514 0 0 0</pose>
        <geometry>
          <mesh>
            <uri>model://x500_hop/meshes/robotic_arm_link_4.stl</uri>
            <scale>0.001 0.001 0.001</scale>
          </mesh>
        </geometry>
      </collision>
    </link>
    <link name="robotic_arm_link_5">
      <pose>-0.094519 -0.004064 0.389014 0 0 0</pose>
      <inertial>
        <pose>-0.0148953638 0.002972509 2.26476461e-07 0 0 0</pose>
        <mass>0.013524532357919387</mass>
        <inertia>
          <ixx>1e-06</ixx>
          <ixy>0.0</ixy>
          <ixz>-0.0</ixz>
          <iyy>1e-06</iyy>
          <iyz>0.0</iyz>
          <izz>1e-06</izz>
        </inertia>
      </inertial>
      <visual name="old_component__23__1_visual">
        <pose>0.094519 0.004064 -0.389014 0 0 0</pose>
        <geometry>
          <mesh>
            <uri>model://x500_hop/meshes/robotic_arm_link_5.stl</uri>
            <scale>0.001 0.001 0.001</scale>
          </mesh>
        </geometry>
                <material>
          <ambient>0.7 0.7 0.7 1</ambient>
          <diffuse>0.7 0.7 0.7 1</diffuse>
          <specular>0.3 0.3 0.3 1</specular>
        </material>
      </visual>
      <collision name="old_component__23__1_collision">
        <pose>0.094519 0.004064 -0.389014 0 0 0</pose>
        <geometry>
          <mesh>
            <uri>model://x500_hop/meshes/robotic_arm_link_5.stl</uri>
            <scale>0.001 0.001 0.001</scale>
          </mesh>
        </geometry>
      </collision>
    </link>
    <link name="robotic_arm_link_6">
      <pose>-0.104469 -0.018864 0.389014 0 0 0</pose>
      <inertial>
        <pose>-6.410580997e-05 -0.01260591307 -0.03856128506 0 0 0</pose>
        <mass>0.03129872704182124</mass>
        <inertia>
          <ixx>0.000168</ixx>
          <ixy>-0.0</ixy>
          <ixz>-1e-06</ixz>
          <iyy>0.000162</iyy>
          <iyz>-2e-05</iyz>
          <izz>1.8e-05</izz>
        </inertia>
      </inertial>
      <visual name="old_component__24__1_visual">
        <pose>0.104469 0.018864 -0.389014 0 0 0</pose>
        <geometry>
          <mesh>
            <uri>model://x500_hop/meshes/robotic_arm_link_6.stl</uri>
            <scale>0.001 0.001 0.001</scale>
          </mesh>
        </geometry>
                <material>
          <ambient>0.7 0.7 0.7 1</ambient>
          <diffuse>0.7 0.7 0.7 1</diffuse>
          <specular>0.3 0.3 0.3 1</specular>
        </material>
      </visual>
      <collision name="old_component__24__1_collision">
        <pose>0.104469 0.018864 -0.389014 0 0 0</pose>
        <geometry>
          <mesh>
            <uri>model://x500_hop/meshes/robotic_arm_link_6.stl</uri>
            <scale>0.001 0.001 0.001</scale>
          </mesh>
        </geometry>
      </collision>
    </link>
    <link name="robotic_arm_wrist_1">
      <pose>-0.119669 -0.011364 0.314014 0 0 0</pose>
      <inertial>
        <pose>0.0155046362 -0.002772581207 2.253589321e-07 0 0 0</pose>
        <mass>0.013524532357919387</mass>
        <inertia>
          <ixx>1e-06</ixx>
          <ixy>-0.0</ixy>
          <ixz>-0.0</ixz>
          <iyy>1e-06</iyy>
          <iyz>-0.0</iyz>
          <izz>1e-06</izz>
        </inertia>
      </inertial>
      <visual name="old_component__25__1_visual">
        <pose>0.119669 0.011364 -0.314014 0 0 0</pose>
        <geometry>
          <mesh>
            <uri>model://x500_hop/meshes/robotic_arm_wrist_1.stl</uri>
            <scale>0.001 0.001 0.001</scale>
          </mesh>
        </geometry>
                <material>
          <ambient>0.7 0.7 0.7 1</ambient>
          <diffuse>0.7 0.7 0.7 1</diffuse>
          <specular>0.3 0.3 0.3 1</specular>
        </material>
      </visual>
      <collision name="old_component__25__1_collision">
        <pose>0.119669 0.011364 -0.314014 0 0 0</pose>
        <geometry>
          <mesh>
            <uri>model://x500_hop/meshes/robotic_arm_wrist_1.stl</uri>
            <scale>0.001 0.001 0.001</scale>
          </mesh>
        </geometry>
      </collision>
    </link>
    <link name="robotic_arm_wrist_2">
      <pose>-0.099219 0.003636 0.314014 0 0 0</pose>
      <inertial>
        <pose>-1.488355725e-05 0.009899766244 2.253356129e-07 0 0 0</pose>
        <mass>0.006541264087950384</mass>
        <inertia>
          <ixx>1e-06</ixx>
          <ixy>-0.0</ixy>
          <ixz>0.0</ixz>
          <iyy>1e-06</iyy>
          <iyz>-0.0</iyz>
          <izz>1e-06</izz>
        </inertia>
      </inertial>
      <visual name="old_component__26__1_visual">
        <pose>0.099219 -0.003636 -0.314014 0 0 0</pose>
        <geometry>
          <mesh>
            <uri>model://x500_hop/meshes/robotic_arm_wrist_2.stl</uri>
            <scale>0.001 0.001 0.001</scale>
          </mesh>
        </geometry>
                <material>
          <ambient>0.7 0.7 0.7 1</ambient>
          <diffuse>0.7 0.7 0.7 1</diffuse>
          <specular>0.3 0.3 0.3 1</specular>
        </material>
      </visual>
      <collision name="old_component__26__1_collision">
        <pose>0.099219 -0.003636 -0.314014 0 0 0</pose>
        <geometry>
          <mesh>
            <uri>model://x500_hop/meshes/robotic_arm_wrist_2.stl</uri>
            <scale>0.001 0.001 0.001</scale>
          </mesh>
        </geometry>
      </collision>
    </link>
    <link name="robotic_arm_gripper_base">
      <pose>-0.099219 0.015886 0.304014 0 0 0</pose>
      <inertial>
        <pose>-3.583181241e-08 -3.610347118e-08 -0.02192356103 0 0 0</pose>
        <mass>0.00826836161503609</mass>
        <inertia>
          <ixx>1e-06</ixx>
          <ixy>0.0</ixy>
          <ixz>0.0</ixz>
          <iyy>1e-06</iyy>
          <iyz>0.0</iyz>
          <izz>1e-06</izz>
        </inertia>
      </inertial>
      <visual name="old_component__27__1_visual">
        <pose>0.099219 -0.015886 -0.304014 0 0 0</pose>
        <geometry>
          <mesh>
            <uri>model://x500_hop/meshes/robotic_arm_gripper_base.stl</uri>
            <scale>0.001 0.001 0.001</scale>
          </mesh>
        </geometry>
                <material>
          <ambient>0.7 0.7 0.7 1</ambient>
          <diffuse>0.7 0.7 0.7 1</diffuse>
          <specular>0.3 0.3 0.3 1</specular>
        </material>
      </visual>
      <collision name="old_component__27__1_collision">
        <pose>0.099219 -0.015886 -0.304014 0 0 0</pose>
        <geometry>
          <mesh>
            <uri>model://x500_hop/meshes/robotic_arm_gripper_base.stl</uri>
            <scale>0.001 0.001 0.001</scale>
          </mesh>
        </geometry>
      </collision>
    </link>
    <link name="robotic_arm_gripper_finger">
      <pose>-0.099219 0.015886 0.259014 0 0 0</pose>
      <inertial>
        <pose>-3.583155256e-08 -3.610347125e-08 2.253589881e-07 0 0 0</pose>
        <mass>8.7122457664796e-05</mass>
        <inertia>
          <ixx>1e-06</ixx>
          <ixy>0.0</ixy>
          <ixz>0.0</ixz>
          <iyy>1e-06</iyy>
          <iyz>0.0</iyz>
          <izz>1e-06</izz>
        </inertia>
      </inertial>
      <visual name="old_component__28__1_visual">
        <pose>0.099219 -0.015886 -0.259014 0 0 0</pose>
        <geometry>
          <mesh>
            <uri>model://x500_hop/meshes/robotic_arm_gripper_finger.stl</uri>
            <scale>0.001 0.001 0.001</scale>
          </mesh>
        </geometry>
                <material>
          <ambient>0.7 0.7 0.7 1</ambient>
          <diffuse>0.7 0.7 0.7 1</diffuse>
          <specular>0.3 0.3 0.3 1</specular>
        </material>
      </visual>
      <collision name="old_component__28__1_collision">
        <pose>0.099219 -0.015886 -0.259014 0 0 0</pose>
        <geometry>
          <mesh>
            <uri>model://x500_hop/meshes/robotic_arm_gripper_finger.stl</uri>
            <scale>0.001 0.001 0.001</scale>
          </mesh>
        </geometry>
      </collision>
    </link>
    <link name="rotor_0">
      <pose>-0.158901 0.158604 0.841043 0 0 0</pose>
      <inertial>
        <pose>-3.062393157e-07 -2.315365763e-07 -0.0111728405 0 0 0</pose>
        <mass>0.010177599076157505</mass>
                <inertia>
          <ixx>1e-06</ixx>
          <iyy>4.7e-05</iyy>
          <izz>4.7e-05</izz>
          <ixy>0.0</ixy>
          <iyz>0.0</iyz>
          <ixz>0.0</ixz>
        </inertia>
      </inertial>
      <visual name="old_component__29__1_visual">
        <pose>0.158901 -0.158604 -0.841043 0 0 0</pose>
        <geometry>
          <mesh>
            <uri>model://x500_hop/meshes/rotor_0.stl</uri>
            <scale>0.001 0.001 0.001</scale>
          </mesh>
        </geometry>
                <material>
          <ambient>0.7 0.7 0.7 1</ambient>
          <diffuse>0.7 0.7 0.7 1</diffuse>
          <specular>0.3 0.3 0.3 1</specular>
        </material>
      </visual>
      <collision name="old_component__29__1_collision">
        <pose>0.158901 -0.158604 -0.841043 0 0 0</pose>
        <geometry>
          <mesh>
            <uri>model://x500_hop/meshes/rotor_0.stl</uri>
            <scale>0.001 0.001 0.001</scale>
          </mesh>
        </geometry>
      </collision>
    </link>
    <link name="rotor_2">
      <pose>-0.158912 -0.159209 0.841043 0 0 0</pose>
      <inertial>
        <pose>3.464030174e-09 -5.222705879e-08 -0.0111728405 0 0 0</pose>
        <mass>0.010177599076157505</mass>
                <inertia>
          <ixx>1e-06</ixx>
          <iyy>4.7e-05</iyy>
          <izz>4.7e-05</izz>
          <ixy>0.0</ixy>
          <iyz>0.0</iyz>
          <ixz>0.0</ixz>
        </inertia>
      </inertial>
      <visual name="old_component__30__1_visual">
        <pose>0.158912 0.159209 -0.841043 0 0 0</pose>
        <geometry>
          <mesh>
            <uri>model://x500_hop/meshes/rotor_2.stl</uri>
            <scale>0.001 0.001 0.001</scale>
          </mesh>
        </geometry>
                <material>
          <ambient>0.7 0.7 0.7 1</ambient>
          <diffuse>0.7 0.7 0.7 1</diffuse>
          <specular>0.3 0.3 0.3 1</specular>
        </material>
      </visual>
      <collision name="old_component__30__1_collision">
        <pose>0.158912 0.159209 -0.841043 0 0 0</pose>
        <geometry>
          <mesh>
            <uri>model://x500_hop/meshes/rotor_2.stl</uri>
            <scale>0.001 0.001 0.001</scale>
          </mesh>
        </geometry>
      </collision>
    </link>
    <link name="rotor_1">
      <pose>0.158901 -0.15922 0.841043 0 0 0</pose>
      <inertial>
        <pose>-1.758454863e-07 2.574762873e-07 -0.0112728405 0 0 0</pose>
        <mass>0.010177599076157505</mass>
                <inertia>
          <ixx>1e-06</ixx>
          <iyy>4.7e-05</iyy>
          <izz>4.7e-05</izz>
          <ixy>0.0</ixy>
          <iyz>0.0</iyz>
          <ixz>0.0</ixz>
        </inertia>
      </inertial>
      <visual name="old_component__31__1_visual">
        <pose>-0.158901 0.15922 -0.841043 0 0 0</pose>
        <geometry>
          <mesh>
            <uri>model://x500_hop/meshes/rotor_1.stl</uri>
            <scale>0.001 0.001 0.001</scale>
          </mesh>
        </geometry>
                <material>
          <ambient>0.7 0.7 0.7 1</ambient>
          <diffuse>0.7 0.7 0.7 1</diffuse>
          <specular>0.3 0.3 0.3 1</specular>
        </material>
      </visual>
      <collision name="old_component__31__1_collision">
        <pose>-0.158901 0.15922 -0.841043 0 0 0</pose>
        <geometry>
          <mesh>
            <uri>model://x500_hop/meshes/rotor_1.stl</uri>
            <scale>0.001 0.001 0.001</scale>
          </mesh>
        </geometry>
      </collision>
    </link>
    <link name="rotor_3">
      <pose>0.158912 0.158593 0.841043 0 0 0</pose>
      <inertial>
        <pose>-4.855488333e-07 7.816677028e-08 -0.0111728405 0 0 0</pose>
        <mass>0.010177599076157505</mass>
                <inertia>
          <ixx>1e-06</ixx>
          <iyy>4.7e-05</iyy>
          <izz>4.7e-05</izz>
          <ixy>0.0</ixy>
          <iyz>0.0</iyz>
          <ixz>0.0</ixz>
        </inertia>
      </inertial>
      <visual name="old_component__32__1_visual">
        <pose>-0.158912 -0.158593 -0.841043 0 0 0</pose>
        <geometry>
          <mesh>
            <uri>model://x500_hop/meshes/rotor_3.stl</uri>
            <scale>0.001 0.001 0.001</scale>
          </mesh>
        </geometry>
                <material>
          <ambient>0.7 0.7 0.7 1</ambient>
          <diffuse>0.7 0.7 0.7 1</diffuse>
          <specular>0.3 0.3 0.3 1</specular>
        </material>
      </visual>
      <collision name="old_component__32__1_collision">
        <pose>-0.158912 -0.158593 -0.841043 0 0 0</pose>
        <geometry>
          <mesh>
            <uri>model://x500_hop/meshes/rotor_3.stl</uri>
            <scale>0.001 0.001 0.001</scale>
          </mesh>
        </geometry>
      </collision>
    </link>
    <joint name="Rigid 1" type="fixed">
      <pose>0 0 0 0 0 0</pose>
      <parent>base_link</parent>
      <child>frame_arm_1</child>
    </joint>
    <joint name="Rigid 2" type="fixed">
      <pose>0 0 0 0 0 0</pose>
      <parent>base_link</parent>
      <child>frame_arm_2</child>
    </joint>
    <joint name="Rigid 3" type="fixed">
      <pose>0 0 0 0 0 0</pose>
      <parent>base_link</parent>
      <child>frame_arm_3</child>
    </joint>
    <joint name="Rigid 4" type="fixed">
      <pose>0 0 0 0 0 0</pose>
      <parent>base_link</parent>
      <child>frame_arm_4</child>
    </joint>
    <joint name="Rigid 5" type="fixed">
      <pose>0 0 0 0 0 0</pose>
      <parent>base_link</parent>
      <child>landing_gear_1</child>
    </joint>
    <joint name="Rigid 6" type="fixed">
      <pose>0 0 0 0 0 0</pose>
      <parent>base_link</parent>
      <child>landing_gear_2</child>
    </joint>
    <joint name="Rigid 7" type="fixed">
      <pose>0 0 0 0 0 0</pose>
      <parent>frame_arm_3</parent>
      <child>frame_mount</child>
    </joint>
    <joint name="Rigid 8" type="fixed">
      <pose>0 0 0 0 0 0</pose>
      <parent>frame_arm_4</parent>
      <child>motor_mount_1</child>
    </joint>
    <joint name="Rigid 9" type="fixed">
      <pose>0 0 0 0 0 0</pose>
      <parent>frame_arm_1</parent>
      <child>motor_mount_2</child>
    </joint>
    <joint name="Rigid 10" type="fixed">
      <pose>0 0 0 0 0 0</pose>
      <parent>frame_arm_2</parent>
      <child>motor_mount_3</child>
    </joint>
    <joint name="Rigid 11" type="fixed">
      <pose>0 0 0 0 0 0</pose>
      <parent>frame_arm_3</parent>
      <child>motor_mount_4</child>
    </joint>
    <joint name="Rigid 16" type="fixed">
      <pose>0 0 0 0 0 0</pose>
      <parent>frame_mount</parent>
      <child>payload_bracket_2</child>
    </joint>
    <joint name="Rigid 17" type="fixed">
      <pose>0 0 0 0 0 0</pose>
      <parent>payload_bracket_2</parent>
      <child>payload_bracket_1</child>
    </joint>
    <joint name="Rigid 18" type="fixed">
      <pose>0 0 0 0 0 0</pose>
      <parent>landing_gear_2</parent>
      <child>arm_mount_bracket</child>
    </joint>
    <joint name="Rigid 19" type="fixed">
      <pose>0 0 0 0 0 0</pose>
      <parent>arm_mount_bracket</parent>
      <child>robotic_arm_base</child>
    </joint>
    <joint name="Revolute 20" type="revolute">
      <pose>0 0 0 0 0 0</pose>
      <parent>robotic_arm_base</parent>
      <child>robotic_arm_link_1</child>
      <axis>
        <xyz>0.0 0.0 -1.0</xyz>
        <dynamics>
          <damping>5.0</damping>
          <friction>0.5</friction>
        </dynamics>
        <limit>
          <lower>-3.141593</lower>
          <upper>3.141593</upper>
          <effort>100</effort>
          <velocity>100</velocity>
        </limit>
      </axis>
    </joint>
    <joint name="Rigid 21" type="fixed">
      <pose>0 0 0 0 0 0</pose>
      <parent>robotic_arm_link_1</parent>
      <child>robotic_arm_motor_casing_1</child>
    </joint>
    <joint name="Revolute 22" type="revolute">
      <pose>0 0 0 0 0 0</pose>
      <parent>robotic_arm_motor_casing_1</parent>
      <child>robotic_arm_link_2</child>
      <axis>
        <xyz>-0.0 -1.0 -0.0</xyz>
        <dynamics>
          <damping>5.0</damping>
          <friction>0.5</friction>
        </dynamics>
        <limit>
          <lower>-1.6</lower>
          <upper>1.6</upper>
          <effort>100</effort>
          <velocity>100</velocity>
        </limit>
      </axis>
    </joint>
    <joint name="Revolute 23" type="revolute">
      <pose>0 0 0 0 0 0</pose>
      <parent>robotic_arm_link_2</parent>
      <child>robotic_arm_link_3</child>
      <axis>
        <xyz>0.0 -1.0 -0.0</xyz>
        <dynamics>
          <damping>5.0</damping>
          <friction>0.5</friction>
        </dynamics>
        <limit>
          <lower>-2.617993</lower>
          <upper>1.570796</upper>
          <effort>100</effort>
          <velocity>100</velocity>
        </limit>
      </axis>
    </joint>
    <joint name="Rigid 24" type="fixed">
      <pose>0 0 0 0 0 0</pose>
      <parent>robotic_arm_link_3</parent>
      <child>robotic_arm_motor_casing_2</child>
    </joint>
    <joint name="Rigid 25" type="fixed">
      <pose>0 0 0 0 0 0</pose>
      <parent>robotic_arm_motor_casing_2</parent>
      <child>robotic_arm_connector</child>
    </joint>
    <joint name="Revolute 26" type="revolute">
      <pose>0 0 0 0 0 0</pose>
      <parent>robotic_arm_connector</parent>
      <child>robotic_arm_link_4</child>
      <axis>
        <xyz>0.0 0.0 -1.0</xyz>
        <dynamics>
          <damping>5.0</damping>
          <friction>0.5</friction>
        </dynamics>
        <limit>
          <lower>-3.141593</lower>
          <upper>3.141593</upper>
          <effort>100</effort>
          <velocity>100</velocity>
        </limit>
      </axis>
    </joint>
    <joint name="Rigid 27" type="fixed">
      <pose>0 0 0 0 0 0</pose>
      <parent>robotic_arm_link_4</parent>
      <child>robotic_arm_link_5</child>
    </joint>
    <joint name="Revolute 28" type="revolute">
      <pose>0 0 0 0 0 0</pose>
      <parent>robotic_arm_link_5</parent>
      <child>robotic_arm_link_6</child>
      <axis>
        <xyz>-0.0 -1.0 -0.0</xyz>
        <dynamics>
          <damping>5.0</damping>
          <friction>0.5</friction>
        </dynamics>
        <limit>
          <lower>-2.356194</lower>
          <upper>2.356194</upper>
          <effort>100</effort>
          <velocity>100</velocity>
        </limit>
      </axis>
    </joint>
    <joint name="Rigid 29" type="fixed">
      <pose>0 0 0 0 0 0</pose>
      <parent>robotic_arm_link_6</parent>
      <child>robotic_arm_wrist_1</child>
    </joint>
    <joint name="Revolute 30" type="revolute">
      <pose>0 0 0 0 0 0</pose>
      <parent>robotic_arm_wrist_1</parent>
      <child>robotic_arm_wrist_2</child>
      <axis>
        <xyz>0.0 1.0 0.0</xyz>
        <dynamics>
          <damping>5.0</damping>
          <friction>0.5</friction>
        </dynamics>
        <limit>
          <lower>0.0</lower>
          <upper>3.141593</upper>
          <effort>100</effort>
          <velocity>100</velocity>
        </limit>
      </axis>
    </joint>
    <joint name="Rigid 32" type="fixed">
      <pose>0 0 0 0 0 0</pose>
      <parent>robotic_arm_wrist_2</parent>
      <child>robotic_arm_gripper_base</child>
    </joint>
    <joint name="Rigid 33" type="fixed">
      <pose>0 0 0 0 0 0</pose>
      <parent>robotic_arm_gripper_base</parent>
      <child>robotic_arm_gripper_finger</child>
    </joint>
    <joint name="Revolute 34" type="revolute">
      <pose>0 0 0 0 0 0</pose>
      <parent>motor_mount_3</parent>
      <child>rotor_0</child>
      <axis>
        <xyz>-0.0 -0.0 1.0</xyz>
        <dynamics>
          <damping>0.004</damping>
          <friction>0</friction>
        </dynamics>
        <limit>
          <lower>-1e+16</lower>
          <upper>1e+16</upper>
          <effort>100</effort>
          <velocity>1000</velocity>
        </limit>
      </axis>
    </joint>
    <joint name="Revolute 35" type="revolute">
      <pose>0 0 0 0 0 0</pose>
      <parent>motor_mount_4</parent>
      <child>rotor_2</child>
      <axis>
        <xyz>0.0 -0.0 1.0</xyz>
        <dynamics>
          <damping>0.004</damping>
          <friction>0</friction>
        </dynamics>
        <limit>
          <lower>-1e+16</lower>
          <upper>1e+16</upper>
          <effort>100</effort>
          <velocity>1000</velocity>
        </limit>
      </axis>
    </joint>
    <joint name="Revolute 36" type="revolute">
      <pose>0 0 0 0 0 0</pose>
      <parent>motor_mount_1</parent>
      <child>rotor_1</child>
      <axis>
        <xyz>0.0 -0.0 1.0</xyz>
        <dynamics>
          <damping>0.004</damping>
          <friction>0</friction>
        </dynamics>
        <limit>
          <lower>-1e+16</lower>
          <upper>1e+16</upper>
          <effort>100</effort>
          <velocity>1000</velocity>
        </limit>
      </axis>
    </joint>
    <joint name="Revolute 37" type="revolute">
      <pose>0 0 0 0 0 0</pose>
      <parent>motor_mount_2</parent>
      <child>rotor_3</child>
      <axis>
        <xyz>-0.0 -0.0 1.0</xyz>
        <dynamics>
          <damping>0.004</damping>
          <friction>0</friction>
        </dynamics>
        <limit>
          <lower>-1e+16</lower>
          <upper>1e+16</upper>
          <effort>100</effort>
          <velocity>1000</velocity>
        </limit>
      </axis>
    </joint>



  <plugin filename="gz-sim-multicopter-motor-model-system" name="gz::sim::systems::MulticopterMotorModel">
    <jointName>Revolute 34</jointName>
    <linkName>rotor_0</linkName>
    <turningDirection>cw</turningDirection>
    <timeConstantUp>0.0125</timeConstantUp>
    <timeConstantDown>0.025</timeConstantDown>
    <maxRotVelocity>2200</maxRotVelocity>
    <motorConstant>3.7e-06</motorConstant>
    <momentConstant>0.016</momentConstant>
    <commandSubTopic>command/motor_speed</commandSubTopic>
    <motorNumber>0</motorNumber>
    <rotorDragCoefficient>8.06e-05</rotorDragCoefficient>
    <rollingMomentCoefficient>1e-06</rollingMomentCoefficient>
    <rotorVelocitySlowdownSim>10</rotorVelocitySlowdownSim>
    <motorType>velocity</motorType>
  </plugin>


  <plugin filename="gz-sim-multicopter-motor-model-system" name="gz::sim::systems::MulticopterMotorModel">
    <jointName>Revolute 36</jointName>
    <linkName>rotor_1</linkName>
    <turningDirection>ccw</turningDirection>
    <timeConstantUp>0.0125</timeConstantUp>
    <timeConstantDown>0.025</timeConstantDown>
    <maxRotVelocity>2200</maxRotVelocity>
    <motorConstant>3.7e-06</motorConstant>
    <momentConstant>0.016</momentConstant>
    <commandSubTopic>command/motor_speed</commandSubTopic>
    <motorNumber>1</motorNumber>
    <rotorDragCoefficient>8.06e-05</rotorDragCoefficient>
    <rollingMomentCoefficient>1e-06</rollingMomentCoefficient>
    <rotorVelocitySlowdownSim>10</rotorVelocitySlowdownSim>
    <motorType>velocity</motorType>
  </plugin>


  <plugin filename="gz-sim-multicopter-motor-model-system" name="gz::sim::systems::MulticopterMotorModel">
    <jointName>Revolute 35</jointName>
    <linkName>rotor_2</linkName>
    <turningDirection>ccw</turningDirection>
    <timeConstantUp>0.0125</timeConstantUp>
    <timeConstantDown>0.025</timeConstantDown>
    <maxRotVelocity>2200</maxRotVelocity>
    <motorConstant>3.7e-06</motorConstant>
    <momentConstant>0.016</momentConstant>
    <commandSubTopic>command/motor_speed</commandSubTopic>
    <motorNumber>2</motorNumber>
    <rotorDragCoefficient>8.06e-05</rotorDragCoefficient>
    <rollingMomentCoefficient>1e-06</rollingMomentCoefficient>
    <rotorVelocitySlowdownSim>10</rotorVelocitySlowdownSim>
    <motorType>velocity</motorType>
  </plugin>


  <plugin filename="gz-sim-multicopter-motor-model-system" name="gz::sim::systems::MulticopterMotorModel">
    <jointName>Revolute 37</jointName>
    <linkName>rotor_3</linkName>
    <turningDirection>cw</turningDirection>
    <timeConstantUp>0.0125</timeConstantUp>
    <timeConstantDown>0.025</timeConstantDown>
    <maxRotVelocity>2200</maxRotVelocity>
    <motorConstant>3.7e-06</motorConstant>
    <momentConstant>0.016</momentConstant>
    <commandSubTopic>command/motor_speed</commandSubTopic>
    <motorNumber>3</motorNumber>
    <rotorDragCoefficient>8.06e-05</rotorDragCoefficient>
    <rollingMomentCoefficient>1e-06</rollingMomentCoefficient>
    <rotorVelocitySlowdownSim>10</rotorVelocitySlowdownSim>
    <motorType>velocity</motorType>
  </plugin>


  <plugin filename="gz-sim-joint-position-controller-system" name="gz::sim::systems::JointPositionController">
    <joint_name>Revolute 20</joint_name>
    <topic>/model/hop/arm/joint1/cmd_pos</topic>
    <p_gain>50.0</p_gain>
    <i_gain>1.0</i_gain>
    <d_gain>2.0</d_gain>
    <cmd_max>20.0</cmd_max>
    <cmd_min>-20.0</cmd_min>
  </plugin>


  <plugin filename="gz-sim-joint-position-controller-system" name="gz::sim::systems::JointPositionController">
    <joint_name>Revolute 22</joint_name>
    <topic>/model/hop/arm/joint2/cmd_pos</topic>
    <p_gain>50.0</p_gain>
    <i_gain>1.0</i_gain>
    <d_gain>2.0</d_gain>
    <cmd_max>20.0</cmd_max>
    <cmd_min>-20.0</cmd_min>
  </plugin>


  <plugin filename="gz-sim-joint-position-controller-system" name="gz::sim::systems::JointPositionController">
    <joint_name>Revolute 23</joint_name>
    <topic>/model/hop/arm/joint3/cmd_pos</topic>
    <p_gain>100.0</p_gain>
    <i_gain>5.0</i_gain>
    <d_gain>5.0</d_gain>
    <cmd_max>100.0</cmd_max>
    <cmd_min>-100.0</cmd_min>
   </plugin>


  <plugin filename="gz-sim-joint-position-controller-system" name="gz::sim::systems::JointPositionController">
    <joint_name>Revolute 26</joint_name>
    <topic>/model/hop/arm/joint4/cmd_pos</topic>
    <p_gain>100.0</p_gain>
    <i_gain>5.0</i_gain>
    <d_gain>5.0</d_gain>
    <cmd_max>100.0</cmd_max>
    <cmd_min>-100.0</cmd_min>
  </plugin>


  <plugin filename="gz-sim-joint-position-controller-system" name="gz::sim::systems::JointPositionController">
    <joint_name>Revolute 28</joint_name>
    <topic>/model/hop/arm/joint5/cmd_pos</topic>
    <p_gain>100.0</p_gain>
    <i_gain>5.0</i_gain>
    <d_gain>5.0</d_gain>
    <cmd_max>100.0</cmd_max>
    <cmd_min>-100.0</cmd_min>
  </plugin>


  <plugin filename="gz-sim-joint-position-controller-system" name="gz::sim::systems::JointPositionController">
    <joint_name>Revolute 30</joint_name>
    <topic>/model/hop/arm/joint6/cmd_pos</topic>
    <p_gain>100.0</p_gain>
    <i_gain>5.0</i_gain>
    <d_gain>5.0</d_gain>
    <cmd_max>100.0</cmd_max>
    <cmd_min>-100.0</cmd_min>
  </plugin>


  <plugin filename="gz-sim-joint-state-publisher-system" name="gz::sim::systems::JointStatePublisher">
    <joint_name>Revolute 20</joint_name>
    <joint_name>Revolute 22</joint_name>
    <joint_name>Revolute 23</joint_name>
    <joint_name>Revolute 26</joint_name>
    <joint_name>Revolute 28</joint_name>
    <joint_name>Revolute 30</joint_name>
    <joint_name>Revolute 34</joint_name>
    <joint_name>Revolute 35</joint_name>
    <joint_name>Revolute 36</joint_name>
    <joint_name>Revolute 37</joint_name>
    <topic>/model/hop/joint_state</topic>
    <update_rate>50</update_rate>
  </plugin>



  <plugin filename="gz-sim-odometry-publisher-system" name="gz::sim::systems::OdometryPublisher">
    <odom_frame>world</odom_frame>
    <robot_base_frame>base_link</robot_base_frame>
    <odom_topic>/model/hop/odometry</odom_topic>
    <tf_topic>/model/hop/tf</tf_topic>
    <update_rate>50</update_rate>
    <dimensions>3</dimensions>
  </plugin>



  <plugin filename="gz-sim-pose-publisher-system" name="gz::sim::systems::PosePublisher">
    <publish_link_pose>true</publish_link_pose>
    <publish_visual_pose>false</publish_visual_pose>
    <publish_collision_pose>false</publish_collision_pose>
    <publish_sensor_pose>false</publish_sensor_pose>
    <update_rate>50</update_rate>
    <topic>/model/hop/pose</topic>
  </plugin>


</model>
</sdf>
