<?xml version="1.0" ?>
<sdf version="1.6">
  <model name="x500_hop">
    <pose>0 0 0.38 0 0 0</pose>
    <self_collide>false</self_collide>
    <static>false</static>

    <!-- ============================================================
         REMOVED: gz-px4-interface-system (no source available)
         Communicate via gz-transport / ROS2 bridge instead
         ============================================================ -->

    <!-- base_link -->
    <link name="base_link">
      <inertial>
        <pose>2.6053033236148976e-09 2.0430511184727322e-05 -0.00030798270803188604 0 0 0</pose>
        <mass>0.15004727239335192</mass>
        <inertia>
          <ixx>0.000118</ixx>
          <iyy>0.000321</iyy>
          <izz>0.000438</izz>
          <ixy>0.0</ixy>
          <iyz>0.0</iyz>
          <ixz>0.0</ixz>
        </inertia>
      </inertial>
      <visual name="base_link_visual">
        <pose>0 0 0 0 0 0</pose>
        <geometry>
          <mesh>
            <uri>model://x500_hop/meshes/base_link.stl</uri>
            <scale>0.001 0.001 0.001</scale>
          </mesh>
        </geometry>
        <material>
          <ambient>0.75 0.75 0.75 1</ambient>
          <diffuse>0.75 0.75 0.75 1</diffuse>
        </material>
      </visual>
      <collision name="base_link_collision">
        <pose>0 0 0 0 0 0</pose>
        <geometry>
          <box><size>0.35 0.35 0.08</size></box>
        </geometry>
        <surface>
          <contact>
            <ode>
              <min_depth>0.001</min_depth>
              <max_vel>0</max_vel>
            </ode>
          </contact>
          <friction>
            <ode/>
          </friction>
        </surface>
      </collision>
      <sensor name="air_pressure_sensor" type="air_pressure">
        <always_on>1</always_on>
        <update_rate>50</update_rate>
        <air_pressure>
          <pressure>
            <noise type="gaussian"><mean>0</mean><stddev>3</stddev></noise>
          </pressure>
        </air_pressure>
      </sensor>
      <sensor name="magnetometer_sensor" type="magnetometer">
        <always_on>1</always_on>
        <update_rate>100</update_rate>
        <magnetometer>
          <x><noise type="gaussian"><stddev>0.0001</stddev></noise></x>
          <y><noise type="gaussian"><stddev>0.0001</stddev></noise></y>
          <z><noise type="gaussian"><stddev>0.0001</stddev></noise></z>
        </magnetometer>
      </sensor>
      <sensor name="imu_sensor" type="imu">
        <always_on>1</always_on>
        <update_rate>250</update_rate>
        <imu>
          <angular_velocity>
            <x><noise type="gaussian"><mean>0.0</mean><stddev>0.0008726646</stddev></noise></x>
            <y><noise type="gaussian"><mean>0.0</mean><stddev>0.0008726646</stddev></noise></y>
            <z><noise type="gaussian"><mean>0.0</mean><stddev>0.0008726646</stddev></noise></z>
          </angular_velocity>
          <linear_acceleration>
            <x><noise type="gaussian"><mean>0.0</mean><stddev>0.00637</stddev></noise></x>
            <y><noise type="gaussian"><mean>0.0</mean><stddev>0.00637</stddev></noise></y>
            <z><noise type="gaussian"><mean>0.0</mean><stddev>0.00686</stddev></noise></z>
          </linear_acceleration>
        </imu>
      </sensor>
      <sensor name="navsat_sensor" type="navsat">
        <always_on>1</always_on>
        <update_rate>30</update_rate>
      </sensor>
    </link>

    <!-- FlameWheel1_1 -->
    <link name="FlameWheel1_1">
      <pose>0.046528 0.031724 0.000493 0 0 0</pose>
      <inertial>
        <pose>0.04808517664329172 0.06258319890001232 0.02771925293099862 0 0 0</pose>
        <mass>0.05463186134644092</mass>
        <inertia>
          <ixx>0.000136</ixx><iyy>0.000136</iyy><izz>0.00026</izz>
          <ixy>-0.000125</ixy><iyz>2e-06</iyz><ixz>2e-06</ixz>
        </inertia>
      </inertial>
      <visual name="FlameWheel1_1_visual">
        <pose>-0.046528 -0.031724 -0.000493 0 0 0</pose>
        <geometry><mesh><uri>model://x500_hop/meshes/FlameWheel1_1.stl</uri><scale>0.001 0.001 0.001</scale></mesh></geometry>
        <material><ambient>0.75 0.75 0.75 1</ambient><diffuse>0.75 0.75 0.75 1</diffuse></material>
      </visual>
      <collision name="FlameWheel1_1_collision">
        <pose>-0.046528 -0.031724 -0.000493 0 0 0</pose>
        <geometry><mesh><uri>model://x500_hop/meshes/FlameWheel1_1.stl</uri><scale>0.001 0.001 0.001</scale></mesh></geometry>
      </collision>
    </link>
    <joint name="Rigid_1" type="fixed">
      <parent>base_link</parent><child>FlameWheel1_1</child>
      <pose>0.046528 0.031724 0.000493 0 0 0</pose>
    </joint>

    <!-- FlameWheel2_1 -->
    <link name="FlameWheel2_1">
      <pose>-0.032032 0.04622 0.000493 0 0 0</pose>
      <inertial>
        <pose>-0.06258316504955494 0.04808521049375068 0.02771925293099859 0 0 0</pose>
        <mass>0.05463186134644092</mass>
        <inertia>
          <ixx>0.000136</ixx><iyy>0.000136</iyy><izz>0.00026</izz>
          <ixy>0.000125</ixy><iyz>2e-06</iyz><ixz>-2e-06</ixz>
        </inertia>
      </inertial>
      <visual name="FlameWheel2_1_visual">
        <pose>0.032032 -0.04622 -0.000493 0 0 0</pose>
        <geometry><mesh><uri>model://x500_hop/meshes/FlameWheel2_1.stl</uri><scale>0.001 0.001 0.001</scale></mesh></geometry>
        <material><ambient>0.75 0.75 0.75 1</ambient><diffuse>0.75 0.75 0.75 1</diffuse></material>
      </visual>
      <collision name="FlameWheel2_1_collision">
        <pose>0.032032 -0.04622 -0.000493 0 0 0</pose>
        <geometry><mesh><uri>model://x500_hop/meshes/FlameWheel2_1.stl</uri><scale>0.001 0.001 0.001</scale></mesh></geometry>
      </collision>
    </link>
    <joint name="Rigid_2" type="fixed">
      <parent>base_link</parent><child>FlameWheel2_1</child>
      <pose>-0.032032 0.04622 0.000493 0 0 0</pose>
    </joint>

    <!-- FlameWheel3_1 -->
    <link name="FlameWheel3_1">
      <pose>-0.046528 -0.03234 0.000493 0 0 0</pose>
      <inertial>
        <pose>-0.04808517664329355 -0.06258313119909603 0.02771925293099868 0 0 0</pose>
        <mass>0.05463186134644092</mass>
        <inertia>
          <ixx>0.000136</ixx><iyy>0.000136</iyy><izz>0.00026</izz>
          <ixy>-0.000125</ixy><iyz>-2e-06</iyz><ixz>-2e-06</ixz>
        </inertia>
      </inertial>
      <visual name="FlameWheel3_1_visual">
        <pose>0.046528 0.03234 -0.000493 0 0 0</pose>
        <geometry><mesh><uri>model://x500_hop/meshes/FlameWheel3_1.stl</uri><scale>0.001 0.001 0.001</scale></mesh></geometry>
        <material><ambient>0.75 0.75 0.75 1</ambient><diffuse>0.75 0.75 0.75 1</diffuse></material>
      </visual>
      <collision name="FlameWheel3_1_collision">
        <pose>0.046528 0.03234 -0.000493 0 0 0</pose>
        <geometry><mesh><uri>model://x500_hop/meshes/FlameWheel3_1.stl</uri><scale>0.001 0.001 0.001</scale></mesh></geometry>
      </collision>
    </link>
    <joint name="Rigid_3" type="fixed">
      <parent>base_link</parent><child>FlameWheel3_1</child>
      <pose>-0.046528 -0.03234 0.000493 0 0 0</pose>
    </joint>

    <!-- FlameWheel4_1 -->
    <link name="FlameWheel4_1">
      <pose>0.046528 -0.03234 0.000493 0 0 0</pose>
      <inertial>
        <pose>0.04808716504955428 -0.06258114279283325 0.027719252930997574 0 0 0</pose>
        <mass>0.05463186134644092</mass>
        <inertia>
          <ixx>0.000136</ixx><iyy>0.000136</iyy><izz>0.00026</izz>
          <ixy>0.000125</ixy><iyz>-2e-06</iyz><ixz>2e-06</ixz>
        </inertia>
      </inertial>
      <visual name="FlameWheel4_1_visual">
        <pose>-0.046528 0.03234 -0.000493 0 0 0</pose>
        <geometry><mesh><uri>model://x500_hop/meshes/FlameWheel4_1.stl</uri><scale>0.001 0.001 0.001</scale></mesh></geometry>
        <material><ambient>0.75 0.75 0.75 1</ambient><diffuse>0.75 0.75 0.75 1</diffuse></material>
      </visual>
      <collision name="FlameWheel4_1_collision">
        <pose>-0.046528 0.03234 -0.000493 0 0 0</pose>
        <geometry><mesh><uri>model://x500_hop/meshes/FlameWheel4_1.stl</uri><scale>0.001 0.001 0.001</scale></mesh></geometry>
      </collision>
    </link>
    <joint name="Rigid_4" type="fixed">
      <parent>base_link</parent><child>FlameWheel4_1</child>
      <pose>0.046528 -0.03234 0.000493 0 0 0</pose>
    </joint>

    <!-- que1_1 -->
    <link name="que1_1">
      <pose>-0.046528 -0.03234 -0.001109 0 0 0</pose>
      <inertial>
        <pose>-0.04286249508799096 9.66641064623075e-08 -0.009976074103039472 0 0 0</pose>
        <mass>0.008835884554512046</mass>
        <inertia><ixx>1e-06</ixx><iyy>7e-06</iyy><izz>7e-06</izz><ixy>0.0</ixy><iyz>0.0</iyz><ixz>0.0</ixz></inertia>
      </inertial>
      <visual name="que1_1_visual">
        <pose>0.046528 0.03234 0.001109 0 0 0</pose>
        <geometry><mesh><uri>model://x500_hop/meshes/que1_1.stl</uri><scale>0.001 0.001 0.001</scale></mesh></geometry>
        <material><ambient>0.75 0.75 0.75 1</ambient><diffuse>0.75 0.75 0.75 1</diffuse></material>
      </visual>
      <collision name="que1_1_collision">
        <pose>0.046528 0.03234 0.001109 0 0 0</pose>
        <geometry><mesh><uri>model://x500_hop/meshes/que1_1.stl</uri><scale>0.001 0.001 0.001</scale></mesh></geometry>
      </collision>
    </link>
    <joint name="Rigid_5" type="fixed">
      <parent>base_link</parent><child>que1_1</child>
      <pose>-0.046528 -0.03234 -0.001109 0 0 0</pose>
    </joint>

    <!-- que2_1 -->
    <link name="que2_1">
      <pose>-0.046528 0.031724 -0.001109 0 0 0</pose>
      <inertial>
        <pose>-0.04286249508799095 -3.127007421749317e-08 -0.009976074103039433 0 0 0</pose>
        <mass>0.008835884554512046</mass>
        <inertia><ixx>1e-06</ixx><iyy>7e-06</iyy><izz>7e-06</izz><ixy>0.0</ixy><iyz>0.0</iyz><ixz>0.0</ixz></inertia>
      </inertial>
      <visual name="que2_1_visual">
        <pose>0.046528 -0.031724 0.001109 0 0 0</pose>
        <geometry><mesh><uri>model://x500_hop/meshes/que2_1.stl</uri><scale>0.001 0.001 0.001</scale></mesh></geometry>
        <material><ambient>0.75 0.75 0.75 1</ambient><diffuse>0.75 0.75 0.75 1</diffuse></material>
      </visual>
      <collision name="que2_1_collision">
        <pose>0.046528 -0.031724 0.001109 0 0 0</pose>
        <geometry><mesh><uri>model://x500_hop/meshes/que2_1.stl</uri><scale>0.001 0.001 0.001</scale></mesh></geometry>
      </collision>
    </link>
    <joint name="Rigid_6" type="fixed">
      <parent>base_link</parent><child>que2_1</child>
      <pose>-0.046528 0.031724 -0.001109 0 0 0</pose>
    </joint>

    <!-- than_tren_1 -->
    <link name="than_tren_1">
      <pose>-0.031466 -0.048083 0.037298 0 0 0</pose>
      <inertial>
        <pose>0.03146602986934658 0.048082604412820446 0.0008261135784801352 0 0 0</pose>
        <mass>0.028714784508064296</mass>
        <inertia><ixx>2.6e-05</ixx><iyy>2.6e-05</iyy><izz>5.2e-05</izz><ixy>0.0</ixy><iyz>0.0</iyz><ixz>0.0</ixz></inertia>
      </inertial>
      <visual name="than_tren_1_visual">
        <pose>0.031466 0.048391 -0.037298 0 0 0</pose>
        <geometry><mesh><uri>model://x500_hop/meshes/than_tren_1.stl</uri><scale>0.001 0.001 0.001</scale></mesh></geometry>
        <material><ambient>0.75 0.75 0.75 1</ambient><diffuse>0.75 0.75 0.75 1</diffuse></material>
      </visual>
      <collision name="than_tren_1_collision">
        <pose>0.031466 0.048391 -0.037298 0 0 0</pose>
        <geometry><mesh><uri>model://x500_hop/meshes/than_tren_1.stl</uri><scale>0.001 0.001 0.001</scale></mesh></geometry>
      </collision>
    </link>
    <joint name="Rigid_7" type="fixed">
      <parent>FlameWheel3_1</parent><child>than_tren_1</child>
      <pose>0.015062 -0.016051 0.036805 0 0 0</pose>
    </joint>

    <!-- motor1_1 -->
    <link name="motor1_1">
      <pose>0.158901 -0.15922 0.037543 0 0 0</pose>
      <inertial>
        <pose>1.7807200139718926e-06 -3.4015928573605247e-06 0.016548296435739844 0 0 0</pose>
        <mass>0.06769610137306545</mass>
        <inertia><ixx>1.3e-05</ixx><iyy>1.3e-05</iyy><izz>7e-06</izz><ixy>0.0</ixy><iyz>0.0</iyz><ixz>0.0</ixz></inertia>
      </inertial>
      <visual name="motor1_1_visual">
        <pose>-0.158901 0.15922 -0.037543 0 0 0</pose>
        <geometry><mesh><uri>model://x500_hop/meshes/motor1_1.stl</uri><scale>0.001 0.001 0.001</scale></mesh></geometry>
        <material><ambient>0.75 0.75 0.75 1</ambient><diffuse>0.75 0.75 0.75 1</diffuse></material>
      </visual>
      <collision name="motor1_1_collision">
        <pose>-0.158901 0.15922 -0.037543 0 0 0</pose>
        <geometry><mesh><uri>model://x500_hop/meshes/motor1_1.stl</uri><scale>0.001 0.001 0.001</scale></mesh></geometry>
      </collision>
    </link>
    <joint name="Rigid_8" type="fixed">
      <parent>FlameWheel4_1</parent><child>motor1_1</child>
      <pose>0.112373 -0.12688 0.03705 0 0 0</pose>
    </joint>

    <!-- motor2_1 -->
    <link name="motor2_1">
      <pose>0.158912 0.158593 0.037543 0 0 0</pose>
      <inertial>
        <pose>1.4710166669207325e-06 -3.5809023752053637e-06 0.01654829643574155 0 0 0</pose>
        <mass>0.06769610137306553</mass>
        <inertia><ixx>1.3e-05</ixx><iyy>1.3e-05</iyy><izz>7e-06</izz><ixy>0.0</ixy><iyz>0.0</iyz><ixz>0.0</ixz></inertia>
      </inertial>
      <visual name="motor2_1_visual">
        <pose>-0.158912 -0.158593 -0.037543 0 0 0</pose>
        <geometry><mesh><uri>model://x500_hop/meshes/motor2_1.stl</uri><scale>0.001 0.001 0.001</scale></mesh></geometry>
        <material><ambient>0.75 0.75 0.75 1</ambient><diffuse>0.75 0.75 0.75 1</diffuse></material>
      </visual>
      <collision name="motor2_1_collision">
        <pose>-0.158912 -0.158593 -0.037543 0 0 0</pose>
        <geometry><mesh><uri>model://x500_hop/meshes/motor2_1.stl</uri><scale>0.001 0.001 0.001</scale></mesh></geometry>
      </collision>
    </link>
    <joint name="Rigid_9" type="fixed">
      <parent>FlameWheel1_1</parent><child>motor2_1</child>
      <pose>0.112384 0.126869 0.03705 0 0 0</pose>
    </joint>

    <!-- motor3_1 -->
    <link name="motor3_1">
      <pose>-0.158901 0.158604 0.037543 0 0 0</pose>
      <inertial>
        <pose>1.6503261845157713e-06 -3.890605721812435e-06 0.016548296435741523 0 0 0</pose>
        <mass>0.06769610137306543</mass>
        <inertia><ixx>1.3e-05</ixx><iyy>1.3e-05</iyy><izz>7e-06</izz><ixy>0.0</ixy><iyz>0.0</iyz><ixz>0.0</ixz></inertia>
      </inertial>
      <visual name="motor3_1_visual">
        <pose>0.158901 -0.158604 -0.037543 0 0 0</pose>
        <geometry><mesh><uri>model://x500_hop/meshes/motor3_1.stl</uri><scale>0.001 0.001 0.001</scale></mesh></geometry>
        <material><ambient>0.75 0.75 0.75 1</ambient><diffuse>0.75 0.75 0.75 1</diffuse></material>
      </visual>
      <collision name="motor3_1_collision">
        <pose>0.158901 -0.158604 -0.037543 0 0 0</pose>
        <geometry><mesh><uri>model://x500_hop/meshes/motor3_1.stl</uri><scale>0.001 0.001 0.001</scale></mesh></geometry>
      </collision>
    </link>
    <joint name="Rigid_10" type="fixed">
      <parent>FlameWheel2_1</parent><child>motor3_1</child>
      <pose>-0.126869 0.112384 0.03705 0 0 0</pose>
    </joint>

    <!-- motor4_1 -->
    <link name="motor4_1">
      <pose>-0.158912 -0.159209 0.037543 0 0 0</pose>
      <inertial>
        <pose>1.9600295304567084e-06 -3.711296204272907e-06 0.016548296435741808 0 0 0</pose>
        <mass>0.06769610137306545</mass>
        <inertia><ixx>1.3e-05</ixx><iyy>1.3e-05</iyy><izz>7e-06</izz><ixy>0.0</ixy><iyz>0.0</iyz><ixz>0.0</ixz></inertia>
      </inertial>
      <visual name="motor4_1_visual">
        <pose>0.158912 0.159209 -0.037543 0 0 0</pose>
        <geometry><mesh><uri>model://x500_hop/meshes/motor4_1.stl</uri><scale>0.001 0.001 0.001</scale></mesh></geometry>
        <material><ambient>0.75 0.75 0.75 1</ambient><diffuse>0.75 0.75 0.75 1</diffuse></material>
      </visual>
      <collision name="motor4_1_collision">
        <pose>0.158912 0.159209 -0.037543 0 0 0</pose>
        <geometry><mesh><uri>model://x500_hop/meshes/motor4_1.stl</uri><scale>0.001 0.001 0.001</scale></mesh></geometry>
      </collision>
    </link>
    <joint name="Rigid_11" type="fixed">
      <parent>FlameWheel3_1</parent><child>motor4_1</child>
      <pose>-0.112384 -0.126869 0.03705 0 0 0</pose>
    </joint>

    <!-- Propellers: cylinder collision thay mesh, damping nhẹ -->
    <link name="quat1_1">
      <pose>-0.158901 0.158604 0.091043 0 0 0</pose>
      <inertial>
        <pose>-6.519691517214987e-08 -2.1065597399783087e-07 0.000500007412540332 0 0 0</pose>
        <mass>0.013237716846839784</mass>
        <inertia><ixx>1e-06</ixx><iyy>3.5e-05</iyy><izz>3.5e-05</izz><ixy>0.0</ixy><iyz>0.0</iyz><ixz>0.0</ixz></inertia>
      </inertial>
      <visual name="quat1_1_visual">
        <pose>0.158901 -0.158604 -0.091043 0 0 0</pose>
        <geometry><mesh><uri>model://x500_hop/meshes/quat1_1.stl</uri><scale>0.001 0.001 0.001</scale></mesh></geometry>
        <material><ambient>0.75 0.75 0.75 1</ambient><diffuse>0.75 0.75 0.75 1</diffuse></material>
      </visual>
      <collision name="quat1_1_collision">
        <pose>0.158901 -0.158604 -0.091043 0 0 0</pose>
        <geometry><cylinder><radius>0.127</radius><length>0.005</length></cylinder></geometry>
      </collision>
    </link>
    <joint name="Revolute_12" type="revolute">
      <parent>motor3_1</parent><child>quat1_1</child>
      <pose>0 0 0.0535 0 0 0</pose>
      <axis>
        <xyz>0 0 1</xyz>
        <limit><lower>-1e+16</lower><upper>1e+16</upper><effort>100</effort><velocity>1000</velocity></limit>
        <dynamics><damping>0.004</damping><friction>0.0</friction></dynamics>
      </axis>
    </joint>

    <link name="quat2_1">
      <pose>-0.158912 -0.159209 0.091043 0 0 0</pose>
      <inertial>
        <pose>2.445064307687872e-07 -3.134645645830325e-08 0.0005000074125406234 0 0 0</pose>
        <mass>0.013237716846839784</mass>
        <inertia><ixx>1e-06</ixx><iyy>3.5e-05</iyy><izz>3.5e-05</izz><ixy>0.0</ixy><iyz>0.0</iyz><ixz>0.0</ixz></inertia>
      </inertial>
      <visual name="quat2_1_visual">
        <pose>0.158912 0.159209 -0.091043 0 0 0</pose>
        <geometry><mesh><uri>model://x500_hop/meshes/quat2_1.stl</uri><scale>0.001 0.001 0.001</scale></mesh></geometry>
        <material><ambient>0.75 0.75 0.75 1</ambient><diffuse>0.75 0.75 0.75 1</diffuse></material>
      </visual>
      <collision name="quat2_1_collision">
        <pose>0.158912 0.159209 -0.091043 0 0 0</pose>
        <geometry><cylinder><radius>0.127</radius><length>0.005</length></cylinder></geometry>
      </collision>
    </link>
    <joint name="Revolute_13" type="revolute">
      <parent>motor4_1</parent><child>quat2_1</child>
      <pose>0 0 0.0535 0 0 0</pose>
      <axis>
        <xyz>0 0 1</xyz>
        <limit><lower>-1e+16</lower><upper>1e+16</upper><effort>100</effort><velocity>1000</velocity></limit>
        <dynamics><damping>0.004</damping><friction>0.0</friction></dynamics>
      </axis>
    </joint>

    <link name="quat3_1">
      <pose>0.158912 0.158593 0.091043 0 0 0</pose>
      <inertial>
        <pose>-2.4450643276718864e-07 9.904737255372886e-08 0.0005000074125404291 0 0 0</pose>
        <mass>0.013237716846839784</mass>
        <inertia><ixx>1e-06</ixx><iyy>3.5e-05</iyy><izz>3.5e-05</izz><ixy>0.0</ixy><iyz>0.0</iyz><ixz>0.0</ixz></inertia>
      </inertial>
      <visual name="quat3_1_visual">
        <pose>-0.158912 -0.158593 -0.091043 0 0 0</pose>
        <geometry><mesh><uri>model://x500_hop/meshes/quat3_1.stl</uri><scale>0.001 0.001 0.001</scale></mesh></geometry>
        <material><ambient>0.75 0.75 0.75 1</ambient><diffuse>0.75 0.75 0.75 1</diffuse></material>
      </visual>
      <collision name="quat3_1_collision">
        <pose>-0.158912 -0.158593 -0.091043 0 0 0</pose>
        <geometry><cylinder><radius>0.127</radius><length>0.005</length></cylinder></geometry>
      </collision>
    </link>
    <joint name="Revolute_14" type="revolute">
      <parent>motor2_1</parent><child>quat3_1</child>
      <pose>0 0 0.0535 0 0 0</pose>
      <axis>
        <xyz>0 0 1</xyz>
        <limit><lower>-1e+16</lower><upper>1e+16</upper><effort>100</effort><velocity>1000</velocity></limit>
        <dynamics><damping>0.004</damping><friction>0.0</friction></dynamics>
      </axis>
    </joint>

    <link name="quat4_1">
      <pose>0.158901 -0.15922 0.091043 0 0 0</pose>
      <inertial>
        <pose>6.519691428397145e-08 2.783568892883448e-07 0.0005000074125386528 0 0 0</pose>
        <mass>0.013237716846839784</mass>
        <inertia><ixx>1e-06</ixx><iyy>3.5e-05</iyy><izz>3.5e-05</izz><ixy>0.0</ixy><iyz>0.0</iyz><ixz>0.0</ixz></inertia>
      </inertial>
      <visual name="quat4_1_visual">
        <pose>-0.158901 0.15922 -0.091043 0 0 0</pose>
        <geometry><mesh><uri>model://x500_hop/meshes/quat4_1.stl</uri><scale>0.001 0.001 0.001</scale></mesh></geometry>
        <material><ambient>0.75 0.75 0.75 1</ambient><diffuse>0.75 0.75 0.75 1</diffuse></material>
      </visual>
      <collision name="quat4_1_collision">
        <pose>-0.158901 0.15922 -0.091043 0 0 0</pose>
        <geometry><cylinder><radius>0.127</radius><length>0.005</length></cylinder></geometry>
      </collision>
    </link>
    <joint name="Revolute_15" type="revolute">
      <parent>motor1_1</parent><child>quat4_1</child>
      <pose>0 0 0.0535 0 0 0</pose>
      <axis>
        <xyz>0 0 1</xyz>
        <limit><lower>-1e+16</lower><upper>1e+16</upper><effort>100</effort><velocity>1000</velocity></limit>
        <dynamics><damping>0.004</damping><friction>0.0</friction></dynamics>
      </axis>
    </joint>

    <!-- pin_1 -->
    <link name="pin_1">
      <pose>0.0 0.038641 0.038432 0 0 0</pose>
      <inertial>
        <pose>0.06999999999999826 -0.039448966149541 -0.02793787840132446 0 0 0</pose>
        <mass>0.5304000000000002</mass>
        <inertia><ixx>0.000137</ixx><iyy>5.7e-05</iyy><izz>0.000159</izz><ixy>0.0</ixy><iyz>0.0</iyz><ixz>0.0</ixz></inertia>
      </inertial>
      <visual name="pin_1_visual">
        <pose>0.0 -0.038641 -0.038432 0 0 0</pose>
        <geometry><mesh><uri>model://x500_hop/meshes/pin_1.stl</uri><scale>0.001 0.001 0.001</scale></mesh></geometry>
        <material><ambient>0.75 0.75 0.75 1</ambient><diffuse>0.75 0.75 0.75 1</diffuse></material>
      </visual>
      <collision name="pin_1_collision">
        <pose>0.0 -0.038641 -0.038432 0 0 0</pose>
        <geometry><box><size>0.14 0.08 0.06</size></box></geometry>
      </collision>
    </link>
    <joint name="Rigid_16" type="fixed">
      <parent>than_tren_1</parent><child>pin_1</child>
      <pose>0.031466 0.087032 0.001134 0 0 0</pose>
    </joint>

    <!-- hop_tren_1 -->
    <link name="hop_tren_1">
      <pose>0.0 -0.000308 0.038949 0 0 0</pose>
      <inertial>
        <pose>-1.723066134218243e-15 3.385045898717399e-08 0.020025121598675553 0 0 0</pose>
        <mass>0.8009999999999998</mass>
        <inertia><ixx>0.000775</ixx><iyy>0.000775</iyy><izz>0.001335</izz><ixy>0.0</ixy><iyz>0.0</iyz><ixz>0.0</ixz></inertia>
      </inertial>
      <visual name="hop_tren_1_visual">
        <pose>0.0 0.000308 -0.038949 0 0 0</pose>
        <geometry><mesh><uri>model://x500_hop/meshes/hop_tren_1.stl</uri><scale>0.001 0.001 0.001</scale></mesh></geometry>
        <material><ambient>0.75 0.75 0.75 1</ambient><diffuse>0.75 0.75 0.75 1</diffuse></material>
      </visual>
      <collision name="hop_tren_1_collision">
        <pose>0.0 0.000308 -0.038949 0 0 0</pose>
        <geometry><box><size>0.18 0.18 0.06</size></box></geometry>
      </collision>
    </link>
    <joint name="Rigid_17" type="fixed">
      <parent>than_tren_1</parent><child>hop_tren_1</child>
      <pose>0.031466 0.048083 0.001651 0 0 0</pose>
    </joint>

    <!-- link0_1 -->
    <link name="link0_1">
      <pose>-0.289055 -0.091552 -0.027218 0 0 0</pose>
      <inertial>
        <pose>0.1745730494213487 0.09124724523116351 0.006646988903384242 0 0 0</pose>
        <mass>0.08574664862455614</mass>
        <inertia><ixx>5.9e-05</ixx><iyy>3.6e-05</iyy><izz>9.1e-05</izz><ixy>0.0</ixy><iyz>0.0</iyz><ixz>0.0</ixz></inertia>
      </inertial>
      <visual name="link0_1_visual">
        <pose>0.289055 0.091552 0.027218 0 0 0</pose>
        <geometry><mesh><uri>model://x500_hop/meshes/link0_1.stl</uri><scale>0.001 0.001 0.001</scale></mesh></geometry>
        <material><ambient>0.75 0.75 0.75 1</ambient><diffuse>0.75 0.75 0.75 1</diffuse></material>
      </visual>
      <collision name="link0_1_collision">
        <pose>0.289055 0.091552 0.027218 0 0 0</pose>
        <geometry><box><size>0.35 0.04 0.03</size></box></geometry>
      </collision>
    </link>
    <joint name="Rigid_18" type="fixed">
      <parent>que2_1</parent><child>link0_1</child>
      <pose>-0.242527 -0.123276 -0.026109 0 0 0</pose>
    </joint>

    <!-- servo0_1 -->
    <link name="servo0_1">
      <pose>-0.090638 0.003586 -0.017359 0 0 0</pose>
      <inertial>
        <pose>-0.024163225541394426 -0.003900040814653351 0.010047459094684724 0 0 0</pose>
        <mass>0.06428973403330858</mass>
        <inertia><ixx>1e-05</ixx><iyy>1.7e-05</iyy><izz>1.1e-05</izz><ixy>0.0</ixy><iyz>0.0</iyz><ixz>0.0</ixz></inertia>
      </inertial>
      <visual name="servo0_1_visual">
        <pose>0.090638 -0.003586 0.017359 0 0 0</pose>
        <geometry><mesh><uri>model://x500_hop/meshes/servo0_1.stl</uri><scale>0.001 0.001 0.001</scale></mesh></geometry>
        <material><ambient>0.75 0.75 0.75 1</ambient><diffuse>0.75 0.75 0.75 1</diffuse></material>
      </visual>
      <collision name="servo0_1_collision">
        <pose>0.090638 -0.003586 0.017359 0 0 0</pose>
        <geometry><box><size>0.05 0.04 0.04</size></box></geometry>
      </collision>
    </link>
    <joint name="Rigid_19" type="fixed">
      <parent>link0_1</parent><child>servo0_1</child>
      <pose>0.198417 0.095138 0.009859 0 0 0</pose>
    </joint>

    <!-- ============================================================
         ARM LINKS — FIX CHÍNH:
         - damping cao (10.0) để chống oscillation do gravity
         - friction đủ lớn để giữ vị trí khi không có lệnh
         - velocity giới hạn 5 rad/s (đủ cho điều khiển thực tế)
         - collision box thay mesh
         ============================================================ -->

    <link name="link1_1">
      <pose>-0.125325 -0.000314 -0.033559 0 0 0</pose>
      <inertial>
        <pose>-0.011220494663761599 0.003097382027377456 -0.015638412726916046 0 0 0</pose>
        <mass>0.07032693622240235</mass>
        <inertia><ixx>5.9e-05</ixx><iyy>8.6e-05</iyy><izz>7.3e-05</izz><ixy>7e-06</ixy><iyz>8e-06</iyz><ixz>-2.5e-05</ixz></inertia>
      </inertial>
      <visual name="link1_1_visual">
        <pose>0.125325 0.000314 0.033559 0 0 0</pose>
        <geometry><mesh><uri>model://x500_hop/meshes/link1_1.stl</uri><scale>0.001 0.001 0.001</scale></mesh></geometry>
        <material><ambient>0.75 0.75 0.75 1</ambient><diffuse>0.75 0.75 0.75 1</diffuse></material>
      </visual>
      <collision name="link1_1_collision">
        <pose>0.125325 0.000314 0.033559 0 0 0</pose>
        <geometry><box><size>0.08 0.03 0.06</size></box></geometry>
      </collision>
    </link>

    <!-- Revolute_20: yaw joint — damping cao chống oscillation -->
    <joint name="Revolute_20" type="revolute">
      <parent>servo0_1</parent>
      <child>link1_1</child>
      <pose>-0.034687 -0.0039 -0.0162 0 0 0</pose>
      <axis>
        <xyz>0 0 -1</xyz>
        <limit>
          <lower>-3.141593</lower><upper>3.141593</upper>
          <effort>100</effort><velocity>5</velocity>
        </limit>
        <dynamics>
          <damping>10.0</damping>
          <friction>0.5</friction>
          <spring_reference>0</spring_reference>
          <spring_stiffness>0</spring_stiffness>
        </dynamics>
      </axis>
    </joint>

    <!-- servo1_1 -->
    <link name="servo1_1">
      <pose>-0.174256 -0.007314 -0.067283 0 0 0</pose>
      <inertial>
        <pose>0.024163195099851376 0.007047415578672501 -0.0038997305117209613 0 0 0</pose>
        <mass>0.06428973403330858</mass>
        <inertia><ixx>1e-05</ixx><iyy>1.1e-05</iyy><izz>1.7e-05</izz><ixy>0.0</ixy><iyz>0.0</iyz><ixz>0.0</ixz></inertia>
      </inertial>
      <visual name="servo1_1_visual">
        <pose>0.174256 0.007314 0.067283 0 0 0</pose>
        <geometry><mesh><uri>model://x500_hop/meshes/servo1_1.stl</uri><scale>0.001 0.001 0.001</scale></mesh></geometry>
        <material><ambient>0.75 0.75 0.75 1</ambient><diffuse>0.75 0.75 0.75 1</diffuse></material>
      </visual>
      <collision name="servo1_1_collision">
        <pose>0.174256 0.007314 0.067283 0 0 0</pose>
        <geometry><box><size>0.05 0.04 0.04</size></box></geometry>
      </collision>
    </link>
    <joint name="Rigid_21" type="fixed">
      <parent>link1_1</parent><child>servo1_1</child>
      <pose>-0.048931 -0.007 -0.033724 0 0 0</pose>
    </joint>

    <!-- link2_1: upper arm -->
    <link name="link2_1">
      <pose>-0.139569 -0.026514 -0.071183 0 0 0</pose>
      <inertial>
        <pose>-3.213157612202977e-08 0.02077669549479448 -0.06562878215738122 0 0 0</pose>
        <mass>0.2221454339235483</mass>
        <inertia><ixx>0.001158</ixx><iyy>0.001009</iyy><izz>0.000324</izz><ixy>0.0</ixy><iyz>-2.7e-05</iyz><ixz>0.0</ixz></inertia>
      </inertial>
      <visual name="link2_1_visual">
        <pose>0.139569 0.026514 0.071183 0 0 0</pose>
        <geometry><mesh><uri>model://x500_hop/meshes/link2_1.stl</uri><scale>0.001 0.001 0.001</scale></mesh></geometry>
        <material><ambient>0.75 0.75 0.75 1</ambient><diffuse>0.75 0.75 0.75 1</diffuse></material>
      </visual>
      <collision name="link2_1_collision">
        <pose>0.139569 0.026514 0.071183 0 0 0</pose>
        <geometry><box><size>0.04 0.06 0.16</size></box></geometry>
      </collision>
    </link>

    <!-- Revolute_22: shoulder pitch — link nặng nhất, cần damping lớn nhất -->
    <joint name="Revolute_22" type="revolute">
      <parent>servo1_1</parent>
      <child>link2_1</child>
      <pose>0.034687 -0.0192 -0.0039 0 0 0</pose>
      <axis>
        <xyz>0 -1 0</xyz>
        <limit>
          <lower>-1.570796</lower><upper>1.570796</upper>
          <effort>100</effort><velocity>5</velocity>
        </limit>
        <dynamics>
          <damping>20.0</damping>
          <friction>1.0</friction>
          <spring_reference>0</spring_reference>
          <spring_stiffness>0</spring_stiffness>
        </dynamics>
      </axis>
    </joint>

    <!-- servo3_1 -->
    <link name="servo3_1">
      <pose>-0.139569 -0.026514 -0.226183 0 0 0</pose>
      <inertial>
        <pose>-0.010523804900148537 0.026247415578672623 2.6948827888673144e-07 0 0 0</pose>
        <mass>0.06428973403330858</mass>
        <inertia><ixx>1e-05</ixx><iyy>1.1e-05</iyy><izz>1.7e-05</izz><ixy>0.0</ixy><iyz>0.0</iyz><ixz>0.0</ixz></inertia>
      </inertial>
      <visual name="servo3_1_visual">
        <pose>0.139569 0.026514 0.226183 0 0 0</pose>
        <geometry><mesh><uri>model://x500_hop/meshes/servo3_1.stl</uri><scale>0.001 0.001 0.001</scale></mesh></geometry>
        <material><ambient>0.75 0.75 0.75 1</ambient><diffuse>0.75 0.75 0.75 1</diffuse></material>
      </visual>
      <collision name="servo3_1_collision">
        <pose>0.139569 0.026514 0.226183 0 0 0</pose>
        <geometry><box><size>0.05 0.04 0.04</size></box></geometry>
      </collision>
    </link>

    <!-- Revolute_23: elbow pitch -->
    <joint name="Revolute_23" type="revolute">
      <parent>link2_1</parent>
      <child>servo3_1</child>
      <pose>0.0 0.0 -0.155 0 0 0</pose>
      <axis>
        <xyz>0 -1 0</xyz>
        <limit>
          <lower>-0.785398</lower><upper>3.909538</upper>
          <effort>100</effort><velocity>5</velocity>
        </limit>
        <dynamics>
          <damping>10.0</damping>
          <friction>0.5</friction>
          <spring_reference>0</spring_reference>
          <spring_stiffness>0</spring_stiffness>
        </dynamics>
      </axis>
    </joint>

    <!-- link3_1 -->
    <link name="link3_1">
      <pose>-0.174256 -0.007314 -0.222283 0 0 0</pose>
      <inertial>
        <pose>0.008245551374481908 0.02356068909805262 -0.023948725047897024 0 0 0</pose>
        <mass>0.14332326599414125</mass>
        <inertia><ixx>0.000117</ixx><iyy>0.000242</iyy><izz>0.000211</izz><ixy>-1e-05</ixy><iyz>-1.2e-05</iyz><ixz>-6.3e-05</ixz></inertia>
      </inertial>
      <visual name="link3_1_visual">
        <pose>0.174256 0.007314 0.222283 0 0 0</pose>
        <geometry><mesh><uri>model://x500_hop/meshes/link3_1.stl</uri><scale>0.001 0.001 0.001</scale></mesh></geometry>
        <material><ambient>0.75 0.75 0.75 1</ambient><diffuse>0.75 0.75 0.75 1</diffuse></material>
      </visual>
      <collision name="link3_1_collision">
        <pose>0.174256 0.007314 0.222283 0 0 0</pose>
        <geometry><box><size>0.10 0.06 0.08</size></box></geometry>
      </collision>
    </link>
    <joint name="Rigid_24" type="fixed">
      <parent>servo3_1</parent><child>link3_1</child>
      <pose>-0.034687 0.0192 0.0039 0 0 0</pose>
    </joint>

    <!-- servo4_1 -->
    <link name="servo4_1">
      <pose>-0.217072 0.028886 -0.256033 0 0 0</pose>
      <inertial>
        <pose>0.002972461544132887 -0.014895364075133427 2.7419945991535855e-07 0 0 0</pose>
        <mass>0.009181225394976135</mass>
        <inertia><ixx>1e-06</ixx><iyy>1e-06</iyy><izz>1e-06</izz><ixy>0.0</ixy><iyz>0.0</iyz><ixz>0.0</ixz></inertia>
      </inertial>
      <visual name="servo4_1_visual">
        <pose>0.217072 -0.028886 0.256033 0 0 0</pose>
        <geometry><mesh><uri>model://x500_hop/meshes/servo4_1.stl</uri><scale>0.001 0.001 0.001</scale></mesh></geometry>
        <material><ambient>0.75 0.75 0.75 1</ambient><diffuse>0.75 0.75 0.75 1</diffuse></material>
      </visual>
      <collision name="servo4_1_collision">
        <pose>0.217072 -0.028886 0.256033 0 0 0</pose>
        <geometry><box><size>0.03 0.03 0.03</size></box></geometry>
      </collision>
    </link>
    <joint name="Rigid_25" type="fixed">
      <parent>link3_1</parent><child>servo4_1</child>
      <pose>-0.042816 0.0362 -0.03375 0 0 0</pose>
    </joint>

    <!-- link4_1 -->
    <link name="link4_1">
      <pose>-0.231872 0.018936 -0.256033 0 0 0</pose>
      <inertial>
        <pose>-0.023912016011001763 -0.0008719393217050744 7.21634633560897e-05 0 0 0</pose>
        <mass>0.03507572795007113</mass>
        <inertia><ixx>1e-05</ixx><iyy>3.5e-05</iyy><izz>3.3e-05</izz><ixy>-3e-06</ixy><iyz>0.0</iyz><ixz>0.0</ixz></inertia>
      </inertial>
      <visual name="link4_1_visual">
        <pose>0.231872 -0.018936 0.256033 0 0 0</pose>
        <geometry><mesh><uri>model://x500_hop/meshes/link4_1.stl</uri><scale>0.001 0.001 0.001</scale></mesh></geometry>
        <material><ambient>0.75 0.75 0.75 1</ambient><diffuse>0.75 0.75 0.75 1</diffuse></material>
      </visual>
      <collision name="link4_1_collision">
        <pose>0.231872 -0.018936 0.256033 0 0 0</pose>
        <geometry><box><size>0.07 0.03 0.03</size></box></geometry>
      </collision>
    </link>

    <!-- Revolute_26: wrist roll -->
    <joint name="Revolute_26" type="revolute">
      <parent>servo4_1</parent>
      <child>link4_1</child>
      <pose>-0.0148 -0.00995 0.0 0 0 0</pose>
      <axis>
        <xyz>-1 0 0</xyz>
        <limit>
          <lower>-3.141593</lower><upper>3.141593</upper>
          <effort>100</effort><velocity>5</velocity>
        </limit>
        <dynamics>
          <damping>5.0</damping>
          <friction>0.3</friction>
          <spring_reference>0</spring_reference>
          <spring_stiffness>0</spring_stiffness>
        </dynamics>
      </axis>
    </joint>

    <!-- servo5_1 -->
    <link name="servo5_1">
      <pose>-0.274372 -0.004064 -0.271233 0 0 0</pose>
      <inertial>
        <pose>-8.355968100781652e-08 0.0029725090003427015 0.014895602171121625 0 0 0</pose>
        <mass>0.009181225394976135</mass>
        <inertia><ixx>1e-06</ixx><iyy>1e-06</iyy><izz>1e-06</izz><ixy>0.0</ixy><iyz>0.0</iyz><ixz>0.0</ixz></inertia>
      </inertial>
      <visual name="servo5_1_visual">
        <pose>0.274372 0.004064 0.271233 0 0 0</pose>
        <geometry><mesh><uri>model://x500_hop/meshes/servo5_1.stl</uri><scale>0.001 0.001 0.001</scale></mesh></geometry>
        <material><ambient>0.75 0.75 0.75 1</ambient><diffuse>0.75 0.75 0.75 1</diffuse></material>
      </visual>
      <collision name="servo5_1_collision">
        <pose>0.274372 0.004064 0.271233 0 0 0</pose>
        <geometry><box><size>0.03 0.03 0.03</size></box></geometry>
      </collision>
    </link>
    <joint name="Rigid_27" type="fixed">
      <parent>link4_1</parent><child>servo5_1</child>
      <pose>-0.0425 -0.023 -0.0152 0 0 0</pose>
    </joint>

    <!-- link5_1 -->
    <link name="link5_1">
      <pose>-0.274372 -0.018864 -0.261283 0 0 0</pose>
      <inertial>
        <pose>-0.03856159509174473 -0.012605913067896837 6.434417684819671e-05 0 0 0</pose>
        <mass>0.06741772217236178</mass>
        <inertia><ixx>3.9e-05</ixx><iyy>0.000348</iyy><izz>0.000361</izz><ixy>-4.3e-05</ixy><iyz>0.0</iyz><ixz>1e-06</ixz></inertia>
      </inertial>
      <visual name="link5_1_visual">
        <pose>0.274372 0.018864 0.261283 0 0 0</pose>
        <geometry><mesh><uri>model://x500_hop/meshes/link5_1.stl</uri><scale>0.001 0.001 0.001</scale></mesh></geometry>
        <material><ambient>0.75 0.75 0.75 1</ambient><diffuse>0.75 0.75 0.75 1</diffuse></material>
      </visual>
      <collision name="link5_1_collision">
        <pose>0.274372 0.018864 0.261283 0 0 0</pose>
        <geometry><box><size>0.12 0.04 0.04</size></box></geometry>
      </collision>
    </link>

    <!-- Revolute_28: forearm pitch -->
    <joint name="Revolute_28" type="revolute">
      <parent>servo5_1</parent>
      <child>link5_1</child>
      <pose>0.0 -0.0148 0.00995 0 0 0</pose>
      <axis>
        <xyz>0 -1 0</xyz>
        <limit>
          <lower>-2.356194</lower><upper>2.356194</upper>
          <effort>100</effort><velocity>5</velocity>
        </limit>
        <dynamics>
          <damping>5.0</damping>
          <friction>0.3</friction>
          <spring_reference>0</spring_reference>
          <spring_stiffness>0</spring_stiffness>
        </dynamics>
      </axis>
    </joint>

    <!-- servo6_1 -->
    <link name="servo6_1">
      <pose>-0.349372 -0.011364 -0.246083 0 0 0</pose>
      <inertial>
        <pose>-8.467726819727517e-08 -0.002772581207285893 -0.015504397828878136 0 0 0</pose>
        <mass>0.009181225394976135</mass>
        <inertia><ixx>1e-06</ixx><iyy>1e-06</iyy><izz>1e-06</izz><ixy>0.0</ixy><iyz>0.0</iyz><ixz>0.0</ixz></inertia>
      </inertial>
      <visual name="servo6_1_visual">
        <pose>0.349372 0.011364 0.246083 0 0 0</pose>
        <geometry><mesh><uri>model://x500_hop/meshes/servo6_1.stl</uri><scale>0.001 0.001 0.001</scale></mesh></geometry>
        <material><ambient>0.75 0.75 0.75 1</ambient><diffuse>0.75 0.75 0.75 1</diffuse></material>
      </visual>
      <collision name="servo6_1_collision">
        <pose>0.349372 0.011364 0.246083 0 0 0</pose>
        <geometry><box><size>0.03 0.03 0.03</size></box></geometry>
      </collision>
    </link>
    <joint name="Rigid_29" type="fixed">
      <parent>link5_1</parent><child>servo6_1</child>
      <pose>-0.075 0.0075 0.0152 0 0 0</pose>
    </joint>

    <!-- hopbut_1 -->
    <link name="hopbut_1">
      <pose>-0.349372 0.003636 -0.266533 0 0 0</pose>
      <inertial>
        <pose>-1.4932402348843965e-05 0.009899766244088204 2.741760852797981e-07 0 0 0</pose>
        <mass>0.0066779628375135906</mass>
        <inertia><ixx>1e-06</ixx><iyy>1e-06</iyy><izz>1e-06</izz><ixy>0.0</ixy><iyz>0.0</iyz><ixz>0.0</ixz></inertia>
      </inertial>
      <visual name="hopbut_1_visual">
        <pose>0.349372 -0.003636 0.266533 0 0 0</pose>
        <geometry><mesh><uri>model://x500_hop/meshes/hopbut_1.stl</uri><scale>0.001 0.001 0.001</scale></mesh></geometry>
        <material><ambient>0.75 0.75 0.75 1</ambient><diffuse>0.75 0.75 0.75 1</diffuse></material>
      </visual>
      <collision name="hopbut_1_collision">
        <pose>0.349372 -0.003636 0.266533 0 0 0</pose>
        <geometry><box><size>0.03 0.03 0.03</size></box></geometry>
      </collision>
    </link>

    <!-- Revolute_30: gripper pitch -->
    <joint name="Revolute_30" type="revolute">
      <parent>servo6_1</parent>
      <child>hopbut_1</child>
      <pose>0.0 0.015 -0.02045 0 0 0</pose>
      <axis>
        <xyz>0 1 0</xyz>
        <limit>
          <lower>0.0</lower><upper>3.141593</upper>
          <effort>100</effort><velocity>5</velocity>
        </limit>
        <dynamics>
          <damping>2.0</damping>
          <friction>0.2</friction>
          <spring_reference>0</spring_reference>
          <spring_stiffness>0</spring_stiffness>
        </dynamics>
      </axis>
    </joint>

    <!-- but_1 -->
    <link name="but_1">
      <pose>-0.349372 0.015886 -0.276533 0 0 0</pose>
      <inertial>
        <pose>-8.467726819727517e-08 -3.610347161162042e-08 -0.024515714354693685 0 0 0</pose>
        <mass>0.009437837434710942</mass>
        <inertia><ixx>2e-06</ixx><iyy>2e-06</iyy><izz>1e-06</izz><ixy>0.0</ixy><iyz>0.0</iyz><ixz>0.0</ixz></inertia>
      </inertial>
      <visual name="but_1_visual">
        <pose>0.349372 -0.015886 0.276533 0 0 0</pose>
        <geometry><mesh><uri>model://x500_hop/meshes/but_1.stl</uri><scale>0.001 0.001 0.001</scale></mesh></geometry>
        <material><ambient>0.75 0.75 0.75 1</ambient><diffuse>0.75 0.75 0.75 1</diffuse></material>
      </visual>
      <collision name="but_1_collision">
        <pose>0.349372 -0.015886 0.276533 0 0 0</pose>
        <geometry><cylinder><radius>0.025</radius><length>0.05</length></cylinder></geometry>
      </collision>
    </link>

    <!-- Revolute_31: spinner — continuous, damping vừa phải -->
    <joint name="Revolute_31" type="revolute">
      <parent>hopbut_1</parent>
      <child>but_1</child>
      <pose>0.0 0.01225 -0.01 0 0 0</pose>
      <axis>
        <xyz>0 0 -1</xyz>
        <limit>
          <lower>-1e+16</lower><upper>1e+16</upper>
          <effort>100</effort><velocity>5</velocity>
        </limit>
        <dynamics>
          <damping>2.0</damping>
          <friction>0.2</friction>
          <spring_reference>0</spring_reference>
          <spring_stiffness>0</spring_stiffness>
        </dynamics>
      </axis>
    </joint>

    <!-- ============================================================
         MOTOR PLUGINS
         ============================================================ -->
    <plugin filename="gz-sim-multicopter-motor-model-system" name="gz::sim::systems::MulticopterMotorModel">
      <jointName>Revolute_15</jointName><linkName>quat4_1</linkName>
      <turningDirection>ccw</turningDirection>
      <timeConstantUp>0.0125</timeConstantUp><timeConstantDown>0.025</timeConstantDown>
      <maxRotVelocity>1500.0</maxRotVelocity>
      <motorConstant>1.24e-05</motorConstant><momentConstant>0.016</momentConstant>
      <commandSubTopic>command/motor_speed</commandSubTopic>
      <motorNumber>0</motorNumber>
      <rotorDragCoefficient>8.06428e-05</rotorDragCoefficient>
      <rollingMomentCoefficient>1e-06</rollingMomentCoefficient>
      <rotorVelocitySlowdownSim>10</rotorVelocitySlowdownSim>
      <motorType>velocity</motorType>
    </plugin>
    <plugin filename="gz-sim-multicopter-motor-model-system" name="gz::sim::systems::MulticopterMotorModel">
      <jointName>Revolute_12</jointName><linkName>quat1_1</linkName>
      <turningDirection>ccw</turningDirection>
      <timeConstantUp>0.0125</timeConstantUp><timeConstantDown>0.025</timeConstantDown>
      <maxRotVelocity>1500.0</maxRotVelocity>
      <motorConstant>1.24e-05</motorConstant><momentConstant>0.016</momentConstant>
      <commandSubTopic>command/motor_speed</commandSubTopic>
      <motorNumber>1</motorNumber>
      <rotorDragCoefficient>8.06428e-05</rotorDragCoefficient>
      <rollingMomentCoefficient>1e-06</rollingMomentCoefficient>
      <rotorVelocitySlowdownSim>10</rotorVelocitySlowdownSim>
      <motorType>velocity</motorType>
    </plugin>
    <plugin filename="gz-sim-multicopter-motor-model-system" name="gz::sim::systems::MulticopterMotorModel">
      <jointName>Revolute_14</jointName><linkName>quat3_1</linkName>
      <turningDirection>cw</turningDirection>
      <timeConstantUp>0.0125</timeConstantUp><timeConstantDown>0.025</timeConstantDown>
      <maxRotVelocity>1500.0</maxRotVelocity>
      <motorConstant>1.24e-05</motorConstant><momentConstant>0.016</momentConstant>
      <commandSubTopic>command/motor_speed</commandSubTopic>
      <motorNumber>2</motorNumber>
      <rotorDragCoefficient>8.06428e-05</rotorDragCoefficient>
      <rollingMomentCoefficient>1e-06</rollingMomentCoefficient>
      <rotorVelocitySlowdownSim>10</rotorVelocitySlowdownSim>
      <motorType>velocity</motorType>
    </plugin>
    <plugin filename="gz-sim-multicopter-motor-model-system" name="gz::sim::systems::MulticopterMotorModel">
      <jointName>Revolute_13</jointName><linkName>quat2_1</linkName>
      <turningDirection>cw</turningDirection>
      <timeConstantUp>0.0125</timeConstantUp><timeConstantDown>0.025</timeConstantDown>
      <maxRotVelocity>1500.0</maxRotVelocity>
      <motorConstant>1.24e-05</motorConstant><momentConstant>0.016</momentConstant>
      <commandSubTopic>command/motor_speed</commandSubTopic>
      <motorNumber>3</motorNumber>
      <rotorDragCoefficient>8.06428e-05</rotorDragCoefficient>
      <rollingMomentCoefficient>1e-06</rollingMomentCoefficient>
      <rotorVelocitySlowdownSim>10</rotorVelocitySlowdownSim>
      <motorType>velocity</motorType>
    </plugin>

    <plugin filename="gz-sim-joint-state-publisher-system" name="gz::sim::systems::JointStatePublisher"/>

    <!-- ============================================================
         JOINT POSITION CONTROLLERS
         PID đã tune lại: p_gain giảm, d_gain tăng mạnh → chống overshoot
         cmd_max/cmd_min giới hạn lực tối đa tránh violent correction
         ============================================================ -->
    <plugin filename="gz-sim-joint-position-controller-system" name="gz::sim::systems::JointPositionController">
      <joint_name>Revolute_20</joint_name>
      <topic>/model/x500_hop/joint/Revolute_20/cmd_pos</topic>
      <p_gain>50.0</p_gain>
      <i_gain>0.1</i_gain>
      <d_gain>20.0</d_gain>
      <i_max>0.5</i_max>
      <i_min>-0.5</i_min>
      <cmd_max>50.0</cmd_max>
      <cmd_min>-50.0</cmd_min>
    </plugin>
    <plugin filename="gz-sim-joint-position-controller-system" name="gz::sim::systems::JointPositionController">
      <joint_name>Revolute_22</joint_name>
      <topic>/model/x500_hop/joint/Revolute_22/cmd_pos</topic>
      <p_gain>50.0</p_gain>
      <i_gain>0.1</i_gain>
      <d_gain>20.0</d_gain>
      <i_max>0.5</i_max>
      <i_min>-0.5</i_min>
      <cmd_max>50.0</cmd_max>
      <cmd_min>-50.0</cmd_min>
    </plugin>
    <plugin filename="gz-sim-joint-position-controller-system" name="gz::sim::systems::JointPositionController">
      <joint_name>Revolute_23</joint_name>
      <topic>/model/x500_hop/joint/Revolute_23/cmd_pos</topic>
      <p_gain>50.0</p_gain>
      <i_gain>0.1</i_gain>
      <d_gain>20.0</d_gain>
      <i_max>0.5</i_max>
      <i_min>-0.5</i_min>
      <cmd_max>50.0</cmd_max>
      <cmd_min>-50.0</cmd_min>
    </plugin>
    <plugin filename="gz-sim-joint-position-controller-system" name="gz::sim::systems::JointPositionController">
      <joint_name>Revolute_26</joint_name>
      <topic>/model/x500_hop/joint/Revolute_26/cmd_pos</topic>
      <p_gain>30.0</p_gain>
      <i_gain>0.05</i_gain>
      <d_gain>10.0</d_gain>
      <i_max>0.5</i_max>
      <i_min>-0.5</i_min>
      <cmd_max>30.0</cmd_max>
      <cmd_min>-30.0</cmd_min>
    </plugin>
    <plugin filename="gz-sim-joint-position-controller-system" name="gz::sim::systems::JointPositionController">
      <joint_name>Revolute_28</joint_name>
      <topic>/model/x500_hop/joint/Revolute_28/cmd_pos</topic>
      <p_gain>30.0</p_gain>
      <i_gain>0.05</i_gain>
      <d_gain>10.0</d_gain>
      <i_max>0.5</i_max>
      <i_min>-0.5</i_min>
      <cmd_max>30.0</cmd_max>
      <cmd_min>-30.0</cmd_min>
    </plugin>
    <plugin filename="gz-sim-joint-position-controller-system" name="gz::sim::systems::JointPositionController">
      <joint_name>Revolute_30</joint_name>
      <topic>/model/x500_hop/joint/Revolute_30/cmd_pos</topic>
      <p_gain>20.0</p_gain>
      <i_gain>0.05</i_gain>
      <d_gain>5.0</d_gain>
      <i_max>0.5</i_max>
      <i_min>-0.5</i_min>
      <cmd_max>20.0</cmd_max>
      <cmd_min>-20.0</cmd_min>
    </plugin>
    <plugin filename="gz-sim-joint-position-controller-system" name="gz::sim::systems::JointPositionController">
      <joint_name>Revolute_31</joint_name>
      <topic>/model/x500_hop/joint/Revolute_31/cmd_pos</topic>
      <p_gain>20.0</p_gain>
      <i_gain>0.05</i_gain>
      <d_gain>5.0</d_gain>
      <i_max>0.5</i_max>
      <i_min>-0.5</i_min>
      <cmd_max>20.0</cmd_max>
      <cmd_min>-20.0</cmd_min>
    </plugin>

  </model>
</sdf>